<?xml version='1.0' encoding='utf-8'?>
<robot name="GR2T2v2_fourier_hand_6dof">
  <link name="base_link">
    <inertial>
      <origin xyz="-0.0030357 6.968E-05 -0.087284" rpy="0 0 0" />
      <mass value="6.6598" />
      <inertia ixx="0.048356" ixy="-1.314E-05" ixz="0.00041517" iyy="0.030781" iyz="-3.242E-05" izz="0.041191" />
    </inertial>
    <visual>
      <origin xyz="0 0 0" rpy="0 0 0" />
      <geometry>
        <mesh filename="../meshes/gr2t2v2/base_link.STL" />
      </geometry>
      <material name="">
        <color rgba="1 1 1 1" />
      </material>
    </visual>
    <collision>
      <origin xyz="0 0.125 0.01" rpy="0 0 0" />
      <geometry>
        <box size="0.18 0.06 0.02" />
      </geometry>
    </collision>
    <collision>
      <origin xyz="0 -0.125 0.01" rpy="0 0 0" />
      <geometry>
        <box size="0.18 0.06 0.02" />
      </geometry>
    </collision>
    <collision>
      <origin xyz="-0.03 0 -0.08" rpy="1.57 0 0" />
      <geometry>
        <cylinder radius="0.1" length="0.17" />
      </geometry>
    </collision>
  </link>
  <link name="waist_yaw_link">
    <inertial>
      <origin xyz="-2.017E-05 8.88E-05 0.024104" rpy="0 0 0" />
      <mass value="0.67252" />
      <inertia ixx="0.0010622" ixy="9E-08" ixz="-4.3E-07" iyy="0.0010624" iyz="3.7E-07" izz="0.00059099" />
    </inertial>
    <visual>
      <origin xyz="0 0 0" rpy="0 0 0" />
      <geometry>
        <mesh filename="../meshes/gr2t2v2/waist_yaw_link.STL" />
      </geometry>
      <material name="">
        <color rgba="1 1 1 1" />
      </material>
    </visual>
    
  </link>
  <joint name="waist_yaw_joint" type="revolute">
    <origin xyz="0 0 -0.0159" rpy="0 0 0" />
    <parent link="base_link" />
    <child link="waist_yaw_link" />
    <axis xyz="0 0 1" />
    <limit lower="-2.618" upper="2.618" effort="74.45" velocity="7.7568" />
  </joint>
  <link name="torso_link">
    <inertial>
      <origin xyz="-0.0054214 0.0010624 -0.12326" rpy="0 0 0" />
      <mass value="14.058" />
      <inertia ixx="0.2545" ixy="0.0001127" ixz="-0.0023" iyy="0.21565" iyz="0.00034939" izz="0.1107" />
    </inertial>
    <visual>
      <origin xyz="0 0 0" rpy="0 0 0" />
      <geometry>
        <mesh filename="../meshes/gr2t2v2/torso_link.STL" />
      </geometry>
      <material name="">
        <color rgba="1 1 1 1" />
      </material>
    </visual>
    <collision>
      <origin xyz="0 0 -0.13" rpy="0 0 0" />
      <geometry>
        <cylinder radius="0.15" length="0.3" />
      </geometry>
    </collision>
  </link>
  <joint name="torso_joint" type="fixed">
    <origin xyz="0 0 0.39681" rpy="0 0 0" />
    <parent link="waist_yaw_link" />
    <child link="torso_link" />
    <axis xyz="0 0 0" />
  </joint>
  <link name="head_yaw_link">
    <inertial>
      <origin xyz="0 0.0099543 0.0065646" rpy="0 0 0" />
      <mass value="0.1402" />
      <inertia ixx="0.00012944" ixy="0" ixz="0" iyy="0.00010676" iyz="-3.991E-05" izz="4.821E-05" />
    </inertial>
    <visual>
      <origin xyz="0 0 0" rpy="0 0 0" />
      <geometry>
        <mesh filename="../meshes/gr2t2v2/head_yaw_link.STL" />
      </geometry>
      <material name="">
        <color rgba="1 1 1 1" />
      </material>
    </visual>
    
  </link>
  <joint name="head_yaw_joint" type="revolute">
    <origin xyz="0.001 0 0.11061" rpy="0 0 0" />
    <parent link="torso_link" />
    <child link="head_yaw_link" />
    <axis xyz="0 0 1" />
    <limit lower="-1.3963" upper="1.3963" effort="17.325" velocity="9.1627" />
  </joint>
  <link name="head_pitch_link">
    <inertial>
      <origin xyz="0.031582 0.0012059 0.072239" rpy="0 0 0" />
      <mass value="1.6096" />
      <inertia ixx="0.0077257" ixy="-1.346E-05" ixz="-0.00055988" iyy="0.010424" iyz="0.00010711" izz="0.0060799" />
    </inertial>
    <visual>
      <origin xyz="0 0 0" rpy="0 0 0" />
      <geometry>
        <mesh filename="../meshes/gr2t2v2/head_pitch_link.STL" />
      </geometry>
      <material name="">
        <color rgba="1 1 1 1" />
      </material>
    </visual>
    <collision>
      <origin xyz="0.02 0 0.07" rpy="0 0 0" />
      <geometry>
        <sphere radius="0.09" />
      </geometry>
    </collision>
  </link>
  <joint name="head_pitch_joint" type="revolute">
    <origin xyz="0 0 0.044185" rpy="0 0 0" />
    <parent link="head_yaw_link" />
    <child link="head_pitch_link" />
    <axis xyz="0 1 0" />
    <limit lower="-0.5236" upper="0.5236" effort="17.325" velocity="9.1627" />
  </joint>
  <link name="camera_link">
    <inertial>
      <origin xyz="0 0 0" rpy="0 0 0" />
      <mass value="0" />
      <inertia ixx="0" ixy="0" ixz="0" iyy="0" iyz="0" izz="0" />
    </inertial>

  </link>
  <joint name="camera_joint" type="fixed">
    <origin xyz="0.11296 0 0.09815" rpy="0 0 0" />
    <parent link="head_pitch_link" />
    <child link="camera_link" />
    <axis xyz="0 0 0" />
  </joint>
  <link name="left_upper_arm_pitch_link">
    <inertial>
      <origin xyz="0.0022312 0.040265 3.797E-05" rpy="0 0 0" />
      <mass value="1.3432" />
      <inertia ixx="0.0031811" ixy="-7.306E-05" ixz="-1.5E-07" iyy="0.0012561" iyz="9E-08" izz="0.0030442" />
    </inertial>
    <visual>
      <origin xyz="0 0 0" rpy="0 0 0" />
      <geometry>
        <mesh filename="../meshes/gr2t2v2/left_upper_arm_pitch_link.STL" />
      </geometry>
      <material name="">
        <color rgba="1 1 1 1" />
      </material>
    </visual>
    
  </link>
  <joint name="left_shoulder_pitch_joint" type="revolute">
    <origin xyz="0 0.15115 0" rpy="0 0 0" />
    <parent link="torso_link" />
    <child link="left_upper_arm_pitch_link" />
    <axis xyz="0 1 0" />
    <limit lower="-2.9671" upper="2.9671" effort="74.45" velocity="7.7568" />
  </joint>
  <link name="left_upper_arm_roll_link">
    <inertial>
      <origin xyz="0.0087432 0.0022878 -0.038787" rpy="0 0 0" />
      <mass value="0.96142" />
      <inertia ixx="0.0026111" ixy="1.105E-05" ixz="-0.00033468" iyy="0.0028017" iyz="2.91E-06" izz="0.00091191" />
    </inertial>
    <visual>
      <origin xyz="0 0 0" rpy="0 0 0" />
      <geometry>
        <mesh filename="../meshes/gr2t2v2/left_upper_arm_roll_link.STL" />
      </geometry>
      <material name="">
        <color rgba="1 1 1 1" />
      </material>
    </visual>
    <collision>
      <origin xyz="0 0 0" rpy="0 0 0" />
      <geometry>
        <sphere radius="0.045" />
      </geometry>
    </collision>
  </link>
  <joint name="left_shoulder_roll_joint" type="revolute">
    <origin xyz="0 0.078848 0" rpy="0 0 0" />
    <parent link="left_upper_arm_pitch_link" />
    <child link="left_upper_arm_roll_link" />
    <axis xyz="1 0 0" />
    <limit lower="-0.5236" upper="2.7925" effort="74.45" velocity="7.7568" />
  </joint>
  <link name="left_upper_arm_yaw_link">
    <inertial>
      <origin xyz="-0.00056161 0.0012137 -0.091108" rpy="0 0 0" />
      <mass value="1.3181" />
      <inertia ixx="0.0067903" ixy="3.2E-07" ixz="-5.12E-06" iyy="0.0068059" iyz="9.238E-05" izz="0.0010853" />
    </inertial>
    <visual>
      <origin xyz="0 0 0" rpy="0 0 0" />
      <geometry>
        <mesh filename="../meshes/gr2t2v2/left_upper_arm_yaw_link.STL" />
      </geometry>
      <material name="">
        <color rgba="1 1 1 1" />
      </material>
    </visual>
    <collision>
      <origin xyz="0 0 -0.05" rpy="0 0 0" />
      <geometry>
        <cylinder radius="0.04" length="0.10" />
      </geometry>
    </collision>
  </link>
  <joint name="left_shoulder_yaw_joint" type="revolute">
    <origin xyz="0 0 -0.09438" rpy="0 0 0" />
    <parent link="left_upper_arm_roll_link" />
    <child link="left_upper_arm_yaw_link" />
    <axis xyz="0 0 1" />
    <limit lower="-1.8326" upper="1.8326" effort="42.75" velocity="6.283" />
  </joint>
  <link name="left_lower_arm_pitch_link">
    <inertial>
      <origin xyz="-0.0014862 0.006973 -0.021097" rpy="0 0 0" />
      <mass value="0.45807" />
      <inertia ixx="0.00068974" ixy="-3.65E-06" ixz="-2.99E-06" iyy="0.00057464" iyz="-6.575E-05" izz="0.00038897" />
    </inertial>
    <visual>
      <origin xyz="0 0 0" rpy="0 0 0" />
      <geometry>
        <mesh filename="../meshes/gr2t2v2/left_lower_arm_pitch_link.STL" />
      </geometry>
      <material name="">
        <color rgba="1 1 1 1" />
      </material>
    </visual>
    
  </link>
  <joint name="left_elbow_pitch_joint" type="revolute">
    <origin xyz="0 0 -0.16111" rpy="0 -0.3926 0" />
    <parent link="left_upper_arm_yaw_link" />
    <child link="left_lower_arm_pitch_link" />
    <axis xyz="0 1 0" />
    <limit lower="-1.5272" upper="0.47997" effort="42.75" velocity="6.283" />
  </joint>
  <link name="left_hand_yaw_link">
    <inertial>
      <origin xyz="0.00027991 0.0038031 -0.062955" rpy="0 0 0" />
      <mass value="1.0855" />
      <inertia ixx="0.0023598" ixy="-9.31E-06" ixz="2.063E-05" iyy="0.002234" iyz="0.00013994" izz="0.00088838" />
    </inertial>
    <visual>
      <origin xyz="0 0 0" rpy="0 0 0" />
      <geometry>
        <mesh filename="../meshes/gr2t2v2/left_hand_yaw_link.STL" />
      </geometry>
      <material name="">
        <color rgba="1 1 1 1" />
      </material>
    </visual>
    <collision>
      <origin xyz="0 0 -0.05" rpy="0 0 0" />
      <geometry>
        <cylinder radius="0.045" length="0.115" />
      </geometry>
    </collision>
  </link>
  <joint name="left_wrist_yaw_joint" type="revolute">
    <origin xyz="0 0 -0.058525" rpy="0 0 0" />
    <parent link="left_lower_arm_pitch_link" />
    <child link="left_hand_yaw_link" />
    <axis xyz="0 0 1" />
    <limit lower="-1.8326" upper="1.8326" effort="17.325" velocity="9.1627" />
  </joint>
  <link name="left_hand_pitch_link">
    <inertial>
      <origin xyz="0.0038604 2.7474E-05 2.9411E-06" rpy="0 0 0" />
      <mass value="0.45716" />
      <inertia ixx="0.00021943" ixy="-3.7E-07" ixz="-8.6975E-08" iyy="0.00022813" iyz="-2.1E-07" izz="0.00023483" />
    </inertial>
    <visual>
      <origin xyz="0 0 0" rpy="0 0 0" />
      <geometry>
        <mesh filename="../meshes/gr2t2v2/left_hand_pitch_link.STL" />
      </geometry>
      <material name="">
        <color rgba="1 1 1 1" />
      </material>
    </visual>
    
  </link>
  <joint name="left_wrist_pitch_joint" type="revolute">
    <origin xyz="0 0 -0.16102" rpy="0 0 0" />
    <parent link="left_hand_yaw_link" />
    <child link="left_hand_pitch_link" />
    <axis xyz="0 1 0" />
    <limit lower="-0.61087" upper="0.61087" effort="17.325" velocity="9.1627" />
  </joint>
  <link name="left_hand_roll_link">
    <inertial>
      <origin xyz="0.0087325 -2.8386E-05 -0.015719" rpy="0 0 0" />
      <mass value="0.20259" />
      <inertia ixx="0.0001134" ixy="-1.8583E-08" ixz="-2.4468E-05" iyy="0.00019338" iyz="-6.0314E-08" izz="0.0001471" />
    </inertial>
    <visual>
      <origin xyz="0 0 0" rpy="0 0 0" />
      <geometry>
        <mesh filename="../meshes/gr2t2v2/left_hand_roll_link.STL" />
      </geometry>
      <material name="">
        <color rgba="1 1 1 1" />
      </material>
    </visual>
    
  </link>
  <joint name="left_wrist_roll_joint" type="revolute">
    <origin xyz="0 0 0" rpy="0 0 0" />
    <parent link="left_hand_pitch_link" />
    <child link="left_hand_roll_link" />
    <axis xyz="1 0 0" />
    <limit lower="-0.95993" upper="0.95993" effort="17.325" velocity="9.1627" />
  </joint>
  <link name="left_end_effector_link">
  </link>
  <joint name="left_end_effector_joint" type="fixed">
    <origin xyz="0 0 -0.045" rpy="0 0 0" />
    <parent link="left_hand_roll_link" />
    <child link="left_end_effector_link" />
    <axis xyz="0 0 0" />
  </joint>


  <link name="right_upper_arm_pitch_link">
    <inertial>
      <origin xyz="0.0022312 -0.040265 3.797E-05" rpy="0 0 0" />
      <mass value="1.3432" />
      <inertia ixx="0.0031811" ixy="7.306E-05" ixz="-1.5E-07" iyy="0.0012561" iyz="-9E-08" izz="0.0030442" />
    </inertial>
    <visual>
      <origin xyz="0 0 0" rpy="0 0 0" />
      <geometry>
        <mesh filename="../meshes/gr2t2v2/right_upper_arm_pitch_link.STL" />
      </geometry>
      <material name="">
        <color rgba="1 1 1 1" />
      </material>
    </visual>
    
  </link>
  <joint name="right_shoulder_pitch_joint" type="revolute">
    <origin xyz="0 -0.1585 0" rpy="0 0 0" />
    <parent link="torso_link" />
    <child link="right_upper_arm_pitch_link" />
    <axis xyz="0 1 0" />
    <limit lower="-2.9671" upper="2.9671" effort="74.45" velocity="7.7568" />
  </joint>
  <link name="right_upper_arm_roll_link">
    <inertial>
      <origin xyz="0.0087432 -0.0022878 -0.038787" rpy="0 0 0" />
      <mass value="0.96142" />
      <inertia ixx="0.0026111" ixy="-1.105E-05" ixz="-0.00033468" iyy="0.0028017" iyz="-2.91E-06" izz="0.00091191" />
    </inertial>
    <visual>
      <origin xyz="0 0 0" rpy="0 0 0" />
      <geometry>
        <mesh filename="../meshes/gr2t2v2/right_upper_arm_roll_link.STL" />
      </geometry>
      <material name="">
        <color rgba="1 1 1 1" />
      </material>
    </visual>
    <collision>
      <origin xyz="0 0 0" rpy="0 0 0" />
      <geometry>
        <sphere radius="0.045" />
      </geometry>
    </collision>
  </link>
  <joint name="right_shoulder_roll_joint" type="revolute">
    <origin xyz="0 -0.071498 0" rpy="0 0 0" />
    <parent link="right_upper_arm_pitch_link" />
    <child link="right_upper_arm_roll_link" />
    <axis xyz="1 0 0" />
    <limit lower="-2.7925" upper="0.5236" effort="74.45" velocity="7.7568" />
  </joint>
  <link name="right_upper_arm_yaw_link">
    <inertial>
      <origin xyz="-0.00056161 -0.0012137 -0.091108" rpy="0 0 0" />
      <mass value="1.3181" />
      <inertia ixx="0.0067903" ixy="-3.2E-07" ixz="-5.12E-06" iyy="0.0068059" iyz="-9.238E-05" izz="0.0010853" />
    </inertial>
    <visual>
      <origin xyz="0 0 0" rpy="0 0 0" />
      <geometry>
        <mesh filename="../meshes/gr2t2v2/right_upper_arm_yaw_link.STL" />
      </geometry>
      <material name="">
        <color rgba="1 1 1 1" />
      </material>
    </visual>
    <collision>
      <origin xyz="0 0 -0.05" rpy="0 0 0" />
      <geometry>
        <cylinder radius="0.040" length="0.1" />
      </geometry>
    </collision>
  </link>
  <joint name="right_shoulder_yaw_joint" type="revolute">
    <origin xyz="0 0 -0.09438" rpy="0 0 0" />
    <parent link="right_upper_arm_roll_link" />
    <child link="right_upper_arm_yaw_link" />
    <axis xyz="0 0 1" />
    <limit lower="-1.8326" upper="1.8326" effort="42.75" velocity="6.283" />
  </joint>
  <link name="right_lower_arm_pitch_link">
    <inertial>
      <origin xyz="-0.0014862 -0.006973 -0.021097" rpy="0 0 0" />
      <mass value="0.45807" />
      <inertia ixx="0.00068974" ixy="3.65E-06" ixz="-2.99E-06" iyy="0.00057464" iyz="6.575E-05" izz="0.00038897" />
    </inertial>
    <visual>
      <origin xyz="0 0 0" rpy="0 0 0" />
      <geometry>
        <mesh filename="../meshes/gr2t2v2/right_lower_arm_pitch_link.STL" />
      </geometry>
      <material name="">
        <color rgba="1 1 1 1" />
      </material>
    </visual>
    
  </link>
  <joint name="right_elbow_pitch_joint" type="revolute">
    <origin xyz="0 0 -0.16111" rpy="0 -0.39265 0" />
    <parent link="right_upper_arm_yaw_link" />
    <child link="right_lower_arm_pitch_link" />
    <axis xyz="0 1 0" />
    <limit lower="-1.5272" upper="0.47997" effort="42.75" velocity="6.283" />
  </joint>
  <link name="right_hand_yaw_link">
    <inertial>
      <origin xyz="0.00027991 -0.0038031 -0.062955" rpy="0 0 0" />
      <mass value="1.0855" />
      <inertia ixx="0.0023598" ixy="9.31E-06" ixz="2.063E-05" iyy="0.002234" iyz="-0.00013994" izz="0.00088838" />
    </inertial>
    <visual>
      <origin xyz="0 0 0" rpy="0 0 0" />
      <geometry>
        <mesh filename="../meshes/gr2t2v2/right_hand_yaw_link.STL" />
      </geometry>
      <material name="">
        <color rgba="1 1 1 1" />
      </material>
    </visual>
    <collision>
      <origin xyz="0 0 -0.05" rpy="0 0 0" />
      <geometry>
        <cylinder radius="0.045" length="0.1155" />
      </geometry>
    </collision>
  </link>
  <joint name="right_wrist_yaw_joint" type="revolute">
    <origin xyz="0 0 -0.058525" rpy="0 0 0" />
    <parent link="right_lower_arm_pitch_link" />
    <child link="right_hand_yaw_link" />
    <axis xyz="0 0 1" />
    <limit lower="-1.8326" upper="1.8326" effort="17.325" velocity="9.1627" />
  </joint>
  <link name="right_hand_pitch_link">
    <inertial>
      <origin xyz="0.0038604 -2.7474E-05 2.9411E-06" rpy="0 0 0" />
      <mass value="0.45716" />
      <inertia ixx="0.00021943" ixy="3.7E-07" ixz="-8.6975E-08" iyy="0.00022813" iyz="2.1E-07" izz="0.00023483" />
    </inertial>
    <visual>
      <origin xyz="0 0 0" rpy="0 0 0" />
      <geometry>
        <mesh filename="../meshes/gr2t2v2/right_hand_pitch_link.STL" />
      </geometry>
      <material name="">
        <color rgba="1 1 1 1" />
      </material>
    </visual>
    
  </link>
  <joint name="right_wrist_pitch_joint" type="revolute">
    <origin xyz="0 0 -0.16102" rpy="0 0 0" />
    <parent link="right_hand_yaw_link" />
    <child link="right_hand_pitch_link" />
    <axis xyz="0 1 0" />
    <limit lower="-0.61087" upper="0.61087" effort="17.325" velocity="9.1627" />
  </joint>
  <link name="right_hand_roll_link">
    <inertial>
      <origin xyz="0.0087325 2.8386E-05 -0.015719" rpy="0 0 0" />
      <mass value="0.20259" />
      <inertia ixx="0.0001134" ixy="1.8583E-08" ixz="-2.4468E-05" iyy="0.00019338" iyz="6.0314E-08" izz="0.0001471" />
    </inertial>
    <visual>
      <origin xyz="0 0 0" rpy="0 0 0" />
      <geometry>
        <mesh filename="../meshes/gr2t2v2/right_hand_roll_link.STL" />
      </geometry>
      <material name="">
        <color rgba="1 1 1 1" />
      </material>
    </visual>
    
  </link>
  <joint name="right_wrist_roll_joint" type="revolute">
    <origin xyz="0 0 0" rpy="0 0 0" />
    <parent link="right_hand_pitch_link" />
    <child link="right_hand_roll_link" />
    <axis xyz="1 0 0" />
    <limit lower="-0.95993" upper="0.95993" effort="17.325" velocity="9.1627" />
  </joint>
  <link name="right_end_effector_link">
  </link>
  <joint name="right_end_effector_joint" type="fixed">
    <origin xyz="0 0 -0.045" rpy="0 0 0" />
    <parent link="right_hand_roll_link" />
    <child link="right_end_effector_link" />
    <axis xyz="0 0 0" />
  </joint>


  <link name="left_thigh_pitch_link">
    <inertial>
      <origin xyz="-0.035065 0.036467 0.0020083" rpy="0 0 0" />
      <mass value="2.61" />
      <inertia ixx="0.0075932" ixy="0.0031974" ixz="-8.035E-05" iyy="0.0085937" iyz="-9.448E-05" izz="0.011716" />
    </inertial>
    <visual>
      <origin xyz="0 0 0" rpy="0 0 0" />
      <geometry>
        <mesh filename="../meshes/gr2t2v2/left_thigh_pitch_link.STL" />
      </geometry>
      <material name="">
        <color rgba="1 1 1 1" />
      </material>
    </visual>
    
  </link>
  <joint name="left_hip_pitch_joint" type="revolute">
    <origin xyz="0 0.076867 -0.12355" rpy="-0.5236 0 0" />
    <parent link="base_link" />
    <child link="left_thigh_pitch_link" />
    <axis xyz="0 1 0" />
    <limit lower="-2.618" upper="2.618" effort="366.05" velocity="6.4997" />
  </joint>
  <link name="left_thigh_roll_link">
    <inertial>
      <origin xyz="0.027776 -0.00010848 -0.0074687" rpy="0 0 0" />
      <mass value="1.3487" />
      <inertia ixx="0.001181" ixy="-5.3E-06" ixz="0.00034163" iyy="0.0026369" iyz="-3.01E-06" izz="0.0027651" />
    </inertial>
    <visual>
      <origin xyz="0 0 0" rpy="0 0 0" />
      <geometry>
        <mesh filename="../meshes/gr2t2v2/left_thigh_roll_link.STL" />
      </geometry>
      <material name="">
        <color rgba="1 1 1 1" />
      </material>
    </visual>

  </link>
  <joint name="left_hip_roll_joint" type="revolute">
    <origin xyz="-0.062 0.0729 0" rpy="0.5236 0 0" />
    <parent link="left_thigh_pitch_link" />
    <child link="left_thigh_roll_link" />
    <axis xyz="1 0 0" />
    <limit lower="-0.59341" upper="1.5708" effort="95.472" velocity="12.362" />
  </joint>
  <link name="left_thigh_yaw_link">
    <inertial>
      <origin xyz="0.0010147 -0.012758 -0.14387" rpy="0 0 0" />
      <mass value="5.1152" />
      <inertia ixx="0.042296" ixy="-8.538E-05" ixz="0.00038855" iyy="0.043183" iyz="0.00098874" izz="0.0099198" />
    </inertial>
    <visual>
      <origin xyz="0 0 0" rpy="0 0 0" />
      <geometry>
        <mesh filename="../meshes/gr2t2v2/left_thigh_yaw_link.STL" />
      </geometry>
      <material name="">
        <color rgba="1 1 1 1" />
      </material>
    </visual>
    <collision>
      <origin xyz="0 0 -0.19" rpy="0 0 0" />
      <geometry>
        <cylinder radius="0.06" length="0.26" />
      </geometry>
    </collision>
  </link>
  <joint name="left_hip_yaw_joint" type="revolute">
    <origin xyz="0.062 0 -0.03495" rpy="0 0 0" />
    <parent link="left_thigh_roll_link" />
    <child link="left_thigh_yaw_link" />
    <axis xyz="0 0 1" />
    <limit lower="-0.69813" upper="1.5708" effort="54.33" velocity="14.745" />
  </joint>
  <link name="left_shank_pitch_link">
    <inertial>
      <origin xyz="0.004743 -0.0014414 -0.1756" rpy="0 0 0" />
      <mass value="3.5932" />
      <inertia ixx="0.034881" ixy="-1.912E-05" ixz="-6.005E-05" iyy="0.035366" iyz="0.0010678" izz="0.0043262" />
    </inertial>
    <visual>
      <origin xyz="0 0 0" rpy="0 0 0" />
      <geometry>
        <mesh filename="../meshes/gr2t2v2/left_shank_pitch_link.STL" />
      </geometry>
      <material name="">
        <color rgba="1 1 1 1" />
      </material>
    </visual>
    <collision>
      <origin xyz="0 0 -0.165" rpy="0 0 0" />
      <geometry>
        <cylinder radius="0.05" length="0.18" />
      </geometry>
    </collision>
  </link>
  <joint name="left_knee_pitch_joint" type="revolute">
    <origin xyz="0 0 -0.34305" rpy="0 0 0" />
    <parent link="left_thigh_yaw_link" />
    <child link="left_shank_pitch_link" />
    <axis xyz="0 1 0" />
    <limit lower="-0.087266" upper="2.3562" effort="366.05" velocity="6.4997" />
  </joint>
  <link name="left_foot_pitch_link">
    <inertial>
      <origin xyz="0.026267 1.226E-05 0.0010987" rpy="0 0 0" />
      <mass value="0.17877" />
      <inertia ixx="1.261E-05" ixy="-9E-08" ixz="5.14E-06" iyy="0.00021914" iyz="-1.8E-07" izz="0.00022011" />
    </inertial>
    <visual>
      <origin xyz="0 0 0" rpy="0 0 0" />
      <geometry>
        <mesh filename="../meshes/gr2t2v2/left_foot_pitch_link.STL" />
      </geometry>
      <material name="">
        <color rgba="1 1 1 1" />
      </material>
    </visual>
    
  </link>
  <joint name="left_ankle_pitch_joint" type="revolute">
    <origin xyz="0 0 -0.406" rpy="0 0 0" />
    <parent link="left_shank_pitch_link" />
    <child link="left_foot_pitch_link" />
    <axis xyz="0 1 0" />
    <limit lower="-0.7854" upper="0.7854" effort="54.33" velocity="14.745" />
  </joint>
  <link name="left_foot_roll_link">
    <inertial>
      <origin xyz="0.050086 0.006159 -0.032795" rpy="0 0 0" />
      <mass value="1.1232" />
      <inertia ixx="0.0012612" ixy="0.00033767" ixz="0.00043059" iyy="0.0067074" iyz="-0.00019341" izz="0.0072126" />
    </inertial>
    <visual>
      <origin xyz="0 0 0" rpy="0 0 0" />
      <geometry>
        <mesh filename="../meshes/gr2t2v2/left_foot_roll_link.STL" />
      </geometry>
      <material name="">
        <color rgba="1 1 1 1" />
      </material>
    </visual>
    


    <collision>
      <origin xyz="0.06 -0.025 -0.033" rpy="0 1.57 0" />
      <geometry>
        <cylinder radius="0.025" length="0.28" />
      </geometry>
    </collision>
    <collision>
      <origin xyz="0.06 0.025 -0.033" rpy="0 1.57 0" />
      <geometry>
        <cylinder radius="0.025" length="0.28" />
      </geometry>
    </collision>
  </link>
  <joint name="left_ankle_roll_joint" type="revolute">
    <origin xyz="0 0 0" rpy="0 0 0" />
    <parent link="left_foot_pitch_link" />
    <child link="left_foot_roll_link" />
    <axis xyz="1 0 0" />
    <limit lower="-0.38397" upper="0.38397" effort="29.835" velocity="16.755" />
  </joint>
  <link name="right_thigh_pitch_link">
    <inertial>
      <origin xyz="-0.035065 -0.036467 0.0020083" rpy="0 0 0" />
      <mass value="2.61" />
      <inertia ixx="0.0075932" ixy="-0.0031974" ixz="-8.035E-05" iyy="0.0085937" iyz="9.448E-05" izz="0.011716" />
    </inertial>
    <visual>
      <origin xyz="0 0 0" rpy="0 0 0" />
      <geometry>
        <mesh filename="../meshes/gr2t2v2/right_thigh_pitch_link.STL" />
      </geometry>
      <material name="">
        <color rgba="1 1 1 1" />
      </material>
    </visual>
    
  </link>
  <joint name="right_hip_pitch_joint" type="revolute">
    <origin xyz="0 -0.076867 -0.12355" rpy="0.5236 0 0" />
    <parent link="base_link" />
    <child link="right_thigh_pitch_link" />
    <axis xyz="0 1 0" />
    <limit lower="-2.618" upper="2.618" effort="366.05" velocity="6.4997" />
  </joint>
  <link name="right_thigh_roll_link">
    <inertial>
      <origin xyz="0.027776 0.00010848 -0.0074687" rpy="0 0 0" />
      <mass value="1.3487" />
      <inertia ixx="0.001181" ixy="5.3E-06" ixz="0.00034163" iyy="0.0026369" iyz="3.01E-06" izz="0.0027651" />
    </inertial>
    <visual>
      <origin xyz="0 0 0" rpy="0 0 0" />
      <geometry>
        <mesh filename="../meshes/gr2t2v2/right_thigh_roll_link.STL" />
      </geometry>
      <material name="">
        <color rgba="1 1 1 1" />
      </material>
    </visual>

  </link>
  <joint name="right_hip_roll_joint" type="revolute">
    <origin xyz="-0.062 -0.0729 0" rpy="-0.5236 0 0" />
    <parent link="right_thigh_pitch_link" />
    <child link="right_thigh_roll_link" />
    <axis xyz="1 0 0" />
    <limit lower="-1.5708" upper="0.59341" effort="95.472" velocity="12.362" />
  </joint>
  <link name="right_thigh_yaw_link">
    <inertial>
      <origin xyz="0.0010147 0.012758 -0.14387" rpy="0 0 0" />
      <mass value="5.1152" />
      <inertia ixx="0.042296" ixy="8.538E-05" ixz="0.00038855" iyy="0.043183" iyz="-0.00098874" izz="0.0099198" />
    </inertial>
    <visual>
      <origin xyz="0 0 0" rpy="0 0 0" />
      <geometry>
        <mesh filename="../meshes/gr2t2v2/right_thigh_yaw_link.STL" />
      </geometry>
      <material name="">
        <color rgba="1 1 1 1" />
      </material>
    </visual>
    <collision>
      <origin xyz="0 0 -0.19" rpy="0 0 0" />
      <geometry>
        <cylinder radius="0.06" length="0.26" />
      </geometry>
    </collision>
  </link>
  <joint name="right_hip_yaw_joint" type="revolute">
    <origin xyz="0.062 0 -0.03495" rpy="0 0 0" />
    <parent link="right_thigh_roll_link" />
    <child link="right_thigh_yaw_link" />
    <axis xyz="0 0 1" />
    <limit lower="-1.5708" upper="0.69813" effort="54.33" velocity="14.745" />
  </joint>
  <link name="right_shank_pitch_link">
    <inertial>
      <origin xyz="0.004743 0.0014414 -0.1756" rpy="0 0 0" />
      <mass value="3.5932" />
      <inertia ixx="0.034881" ixy="1.912E-05" ixz="-6.005E-05" iyy="0.035366" iyz="-0.0010678" izz="0.0043262" />
    </inertial>
    <visual>
      <origin xyz="0 0 0" rpy="0 0 0" />
      <geometry>
        <mesh filename="../meshes/gr2t2v2/right_shank_pitch_link.STL" />
      </geometry>
      <material name="">
        <color rgba="1 1 1 1" />
      </material>
    </visual>
    <collision>
      <origin xyz="0 0 -0.165" rpy="0 0 0" />
      <geometry>
        <cylinder radius="0.05" length="0.18" />
      </geometry>
    </collision>
  </link>
  <joint name="right_knee_pitch_joint" type="revolute">
    <origin xyz="0 0 -0.34305" rpy="0 0 0" />
    <parent link="right_thigh_yaw_link" />
    <child link="right_shank_pitch_link" />
    <axis xyz="0 1 0" />
    <limit lower="-0.087266" upper="2.3562" effort="366.05" velocity="6.4997" />
  </joint>
  <link name="right_foot_pitch_link">
    <inertial>
      <origin xyz="0.026267 -1.226E-05 0.0010987" rpy="0 0 0" />
      <mass value="0.17877" />
      <inertia ixx="1.261E-05" ixy="9E-08" ixz="5.14E-06" iyy="0.00021914" iyz="1.8E-07" izz="0.00022011" />
    </inertial>
    <visual>
      <origin xyz="0 0 0" rpy="0 0 0" />
      <geometry>
        <mesh filename="../meshes/gr2t2v2/right_foot_pitch_link.STL" />
      </geometry>
      <material name="">
        <color rgba="1 1 1 1" />
      </material>
    </visual>
    
  </link>
  <joint name="right_ankle_pitch_joint" type="revolute">
    <origin xyz="0 0 -0.406" rpy="0 0 0" />
    <parent link="right_shank_pitch_link" />
    <child link="right_foot_pitch_link" />
    <axis xyz="0 1 0" />
    <limit lower="-0.7854" upper="0.7854" effort="54.33" velocity="14.745" />
  </joint>
  <link name="right_foot_roll_link">
    <inertial>
      <origin xyz="0.050086 -0.006159 -0.032795" rpy="0 0 0" />
      <mass value="1.1232" />
      <inertia ixx="0.0012612" ixy="-0.00033767" ixz="0.00043059" iyy="0.0067074" iyz="0.00019341" izz="0.0072126" />
    </inertial>
    <visual>
      <origin xyz="0 0 0" rpy="0 0 0" />
      <geometry>
        <mesh filename="../meshes/gr2t2v2/right_foot_roll_link.STL" />
      </geometry>
      <material name="">
        <color rgba="1 1 1 1" />
      </material>
    </visual>
    

    <collision>
      <origin xyz="0.06 -0.025 -0.033" rpy="0 1.57 0" />
      <geometry>
        <cylinder radius="0.025" length="0.28" />
      </geometry>
    </collision>
    <collision>
      <origin xyz="0.06 0.025 -0.033" rpy="0 1.57 0" />
      <geometry>
        <cylinder radius="0.025" length="0.28" />
      </geometry>
    </collision>
  </link>
  <joint name="right_ankle_roll_joint" type="revolute">
    <origin xyz="0 0 0" rpy="0 0 0" />
    <parent link="right_foot_pitch_link" />
    <child link="right_foot_roll_link" />
    <axis xyz="1 0 0" />
    <limit lower="-0.38397" upper="0.38397" effort="29.835" velocity="16.755" />
  </joint>
  <link name="imu_link">
    <inertial>
      <origin xyz="0 0 0" rpy="0 0 0" />
      <mass value="0" />
      <inertia ixx="0" ixy="0" ixz="0" iyy="0" iyz="0" izz="0" />
    </inertial>

  </link>
  <joint name="imu_joint" type="fixed">
    <origin xyz="-0.059 0 -0.068" rpy="0 0 0" />
    <parent link="base_link" />
    <child link="imu_link" />
    <axis xyz="0 0 0" />
  </joint>
<link name="L_hand_base_link">
    <inertial>
      <origin xyz="-0.002551 -0.066047 -0.0019357" rpy="0 0 0" />
      <mass value="0.14143" />
      <inertia ixx="0.0001234" ixy="2.1995E-06" ixz="-1.7694E-06" iyy="8.3835E-05" iyz="1.5968E-06" izz="7.7231E-05" />
    </inertial>
    <visual>
      <origin xyz="0 0 0" rpy="1.570796 0 1.570796" />
      <geometry>
        <mesh filename="../meshes/inspire_hand/base_link_l.STL" />
      </geometry>
      <material name="">
        <color rgba="1 1 1 1" />
      </material>
    </visual>
  </link>

  <link name="L_hand_wrist_link">
  </link>
  <link name="L_thumb_proximal_base">
    <inertial>
      <origin xyz="-0.0048817 0.00038782 -0.00722" rpy="0 0 0" />
      <mass value="0.0018869" />
      <inertia ixx="5.5158E-08" ixy="-1.1803E-08" ixz="-4.6743E-09" iyy="8.2164E-08" iyz="-1.3521E-09" izz="6.7434E-08" />
    </inertial>
    <visual>
      <origin xyz="0 0 0" rpy="0 0 0" />
      <geometry>
        <mesh filename="../meshes/inspire_hand/Link11_l.STL" />
      </geometry>
      <material name="">
        <color rgba="0.82745 0.83922 0.82745 1" />
      </material>
    </visual>
  </link>

  <link name="L_thumb_proximal">
    <inertial>
      <origin xyz="0.021936 -0.01279 -0.0080386" rpy="0 0 0" />
      <mass value="0.0066101" />
      <inertia ixx="1.5693E-06" ixy="7.8339E-07" ixz="8.5959E-10" iyy="1.7356E-06" iyz="1.0378E-09" izz="2.787E-06" />
    </inertial>
    <visual>
      <origin xyz="0 0 0" rpy="0 0 0" />
      <geometry>
        <mesh filename="../meshes/inspire_hand/Link12_l.STL" />
      </geometry>
      <material name="">
        <color rgba="1 1 1 1" />
      </material>
    </visual>
  </link>

  <link name="L_thumb_intermediate">
    <inertial>
      <origin xyz="0.0095531 0.0016282 -0.0072002" rpy="0 0 0" />
      <mass value="0.0037844" />
      <inertia ixx="3.6981E-07" ixy="9.8603E-08" ixz="-2.8173E-12" iyy="3.2395E-07" iyz="-2.8028E-12" izz="4.6532E-07" />
    </inertial>
    <visual>
      <origin xyz="0 0 0" rpy="0 0 0" />
      <geometry>
        <mesh filename="../meshes/inspire_hand/Link13_l.STL" />
      </geometry>
      <material name="">
        <color rgba="1 1 1 1" />
      </material>
    </visual>
  </link>

  <link name="L_thumb_distal">
    <inertial>
      <origin xyz="0.0092888 -0.004953 -0.0060033" rpy="0 0 0" />
      <mass value="0.003344" />
      <inertia ixx="1.3632E-07" ixy="5.6787E-08" ixz="-9.1939E-11" iyy="1.4052E-07" iyz="1.2145E-10" izz="2.0026E-07" />
    </inertial>
    <visual>
      <origin xyz="0 0 0" rpy="0 0 0" />
      <geometry>
        <mesh filename="../meshes/inspire_hand/Link14_l.STL" />
      </geometry>
      <material name="">
        <color rgba="1 1 1 1" />
      </material>
    </visual>
  </link>

  <link name="L_thumb_tip">
    <visual>
      <origin xyz="0 0 0" rpy="0 0 0" />
      <geometry>
        <sphere radius="0.005" />
      </geometry>
      <material name="green">
        <color rgba="0 1 0 1" />
      </material>
    </visual>
  </link>
  <link name="L_index_proximal">
    <inertial>
      <origin xyz="0.0012971 -0.011934 -0.0059998" rpy="0 0 0" />
      <mass value="0.0042405" />
      <inertia ixx="6.6215E-07" ixy="1.8442E-08" ixz="1.3746E-12" iyy="2.1167E-07" iyz="-1.4773E-11" izz="6.9402E-07" />
    </inertial>
    <visual>
      <origin xyz="0 0 0" rpy="0 0 0" />
      <geometry>
        <mesh filename="../meshes/inspire_hand/Link15_l.STL" />
      </geometry>
      <material name="">
        <color rgba="0.79216 0.81961 0.93333 1" />
      </material>
    </visual>
  </link>

  <link name="L_index_intermediate">
    <inertial>
      <origin xyz="0.0021753 -0.019567 -0.005" rpy="0 0 0" />
      <mass value="0.0045682" />
      <inertia ixx="7.6284E-07" ixy="-8.063E-08" ixz="3.6797E-13" iyy="9.4308E-08" iyz="1.5743E-13" izz="7.8176E-07" />
    </inertial>
    <visual>
      <origin xyz="0 0 0" rpy="0 0 0" />
      <geometry>
        <mesh filename="../meshes/inspire_hand/Link16_l.STL" />
      </geometry>
      <material name="">
        <color rgba="1 1 1 1" />
      </material>
    </visual>
  </link>

  <link name="L_index_tip">
    <visual>
      <origin xyz="0 0 0" rpy="0 0 0" />
      <geometry>
        <sphere radius="0.005" />
      </geometry>
      <material name="green">
        <color rgba="0 1 0 1" />
      </material>
    </visual>
  </link>
  <link name="L_middle_proximal">
    <inertial>
      <origin xyz="0.0012971 -0.011934 -0.0059999" rpy="0 0 0" />
      <mass value="0.0042405" />
      <inertia ixx="6.6215E-07" ixy="1.8442E-08" ixz="1.2299E-12" iyy="2.1167E-07" iyz="-1.4484E-11" izz="6.9402E-07" />
    </inertial>
    <visual>
      <origin xyz="0 0 0" rpy="0 0 0" />
      <geometry>
        <mesh filename="../meshes/inspire_hand/Link17_l.STL" />
      </geometry>
      <material name="">
        <color rgba="0.79216 0.81961 0.93333 1" />
      </material>
    </visual>
  </link>

  <link name="L_middle_intermediate">
    <inertial>
      <origin xyz="0.001921 -0.020796 -0.0049999" rpy="0 0 0" />
      <mass value="0.0050397" />
      <inertia ixx="9.5823E-07" ixy="-1.1425E-07" ixz="-2.4186E-12" iyy="1.0646E-07" iyz="3.6974E-12" izz="9.8385E-07" />
    </inertial>
    <visual>
      <origin xyz="0 0 0" rpy="0 0 0" />
      <geometry>
        <mesh filename="../meshes/inspire_hand/Link18_l.STL" />
      </geometry>
      <material name="">
        <color rgba="0.82745 0.83922 0.82745 1" />
      </material>
    </visual>
  </link>

  <link name="L_middle_tip">
    <visual>
      <origin xyz="0 0 0" rpy="0 0 0" />
      <geometry>
        <sphere radius="0.005" />
      </geometry>
      <material name="green">
        <color rgba="0 1 0 1" />
      </material>
    </visual>
  </link>
  <link name="L_ring_proximal">
    <inertial>
      <origin xyz="0.0012971 -0.011934 -0.0059999" rpy="0 0 0" />
      <mass value="0.0042405" />
      <inertia ixx="6.6215E-07" ixy="1.8442E-08" ixz="9.6052E-13" iyy="2.1167E-07" iyz="-1.4124E-11" izz="6.9402E-07" />
    </inertial>
    <visual>
      <origin xyz="0 0 0" rpy="0 0 0" />
      <geometry>
        <mesh filename="../meshes/inspire_hand/Link19_l.STL" />
      </geometry>
      <material name="">
        <color rgba="0.79216 0.81961 0.93333 1" />
      </material>
    </visual>
  </link>

  <link name="L_ring_intermediate">
    <inertial>
      <origin xyz="0.0021753 -0.019567 -0.005" rpy="0 0 0" />
      <mass value="0.0045682" />
      <inertia ixx="7.6285E-07" ixy="-8.0631E-08" ixz="3.3472E-14" iyy="9.4308E-08" iyz="-4.4773E-13" izz="7.8176E-07" />
    </inertial>
    <visual>
      <origin xyz="0 0 0" rpy="0 0 0" />
      <geometry>
        <mesh filename="../meshes/inspire_hand/Link20_l.STL" />
      </geometry>
      <material name="">
        <color rgba="1 1 1 1" />
      </material>
    </visual>
  </link>

  <link name="L_ring_tip">
    <visual>
      <origin xyz="0 0 0" rpy="0 0 0" />
      <geometry>
        <sphere radius="0.005" />
      </geometry>
      <material name="green">
        <color rgba="0 1 0 1" />
      </material>
    </visual>
  </link>
  <link name="L_pinky_proximal">
    <inertial>
      <origin xyz="0.0012971 -0.011934 -0.0059999" rpy="0 0 0" />
      <mass value="0.0042405" />
      <inertia ixx="6.6215E-07" ixy="1.8442E-08" ixz="1.0279E-12" iyy="2.1167E-07" iyz="-1.4277E-11" izz="6.9402E-07" />
    </inertial>
    <visual>
      <origin xyz="0 0 0" rpy="0 0 0" />
      <geometry>
        <mesh filename="../meshes/inspire_hand/Link21_l.STL" />
      </geometry>
      <material name="">
        <color rgba="0.79216 0.81961 0.93333 1" />
      </material>
    </visual>
  </link>

  <link name="L_pinky_intermediate">
    <inertial>
      <origin xyz="0.0024788 -0.016208 -0.0050001" rpy="0 0 0" />
      <mass value="0.0036036" />
      <inertia ixx="4.3923E-07" ixy="-4.1355E-08" ixz="1.2263E-12" iyy="7.0315E-08" iyz="3.1311E-12" izz="4.4881E-07" />
    </inertial>
    <visual>
      <origin xyz="0 0 0" rpy="0 0 0" />
      <geometry>
        <mesh filename="../meshes/inspire_hand/Link22_l.STL" />
      </geometry>
      <material name="">
        <color rgba="1 1 1 1" />
      </material>
    </visual>
  </link>

  <link name="L_pinky_tip">
    <visual>
      <origin xyz="0 0 0" rpy="0 0 0" />
      <geometry>
        <sphere radius="0.005" />
      </geometry>
      <material name="green">
        <color rgba="0 1 0 1" />
      </material>
    </visual>
  </link>
  <joint name="L_hand_wrist_joint" type="fixed">
    <origin xyz="0 0 0" rpy="0 0 0" />
    <parent link="L_hand_base_link" />
    <child link="L_hand_wrist_link" />
    <axis xyz="0 0 0" />
  </joint>

  <joint name="L_thumb_proximal_yaw_joint" type="revolute">
    <origin xyz="0.02045 -0.01696 -0.0691" rpy="3.14 0 0" />
    <parent link="L_hand_base_link" />
    <child link="L_thumb_proximal_base" />
    <axis xyz="0 0 1" />
    <limit lower="-0.1" upper="1.3" effort="1" velocity="0.5" />
  </joint>

  <joint name="L_thumb_proximal_pitch_joint" type="revolute">
    <origin xyz="0.0099867 0.0098242 -0.0089" rpy="-1.5708 0 0.16939" />
    <parent link="L_thumb_proximal_base" />
    <child link="L_thumb_proximal" />
    <axis xyz="0 0 -1" />
    <limit lower="-0.1" upper="0.6" effort="1" velocity="0.5" />
  </joint>

  <joint name="L_thumb_intermediate_joint" type="revolute">
    <origin xyz="0.04407 -0.034553 -0.0008" rpy="0 0 0" />
    <parent link="L_thumb_proximal" />
    <child link="L_thumb_intermediate" />
    <axis xyz="0 0 -1" />
    <limit lower="0" upper="0.8" effort="1" velocity="0.5" />
    <mimic joint="L_thumb_proximal_pitch_joint" multiplier="1.6" offset="0" />
  </joint>

  <joint name="L_thumb_distal_joint" type="revolute">
    <origin xyz="0.020248 -0.010156 -0.0012" rpy="0 0 0" />
    <parent link="L_thumb_intermediate" />
    <child link="L_thumb_distal" />
    <axis xyz="0 0 -1" />
    <limit lower="0" upper="1.2" effort="1" velocity="0.5" />
    <mimic joint="L_thumb_proximal_pitch_joint" multiplier="2.4" offset="0" />
  </joint>


  <joint name="L_thumb_tip_joint" type="fixed">
    <parent link="L_thumb_distal" />
    <child link="L_thumb_tip" />
    <origin rpy="0 0 0" xyz="0.015 -0.013 -0.004" />
  </joint>


  <joint name="L_index_proximal_joint" type="revolute">
    <origin xyz="0.032268 0.00028533 -0.13653" rpy="1.5708 -0.034907 1.5708" />
    <parent link="L_hand_base_link" />
    <child link="L_index_proximal" />
    <axis xyz="0 0 -1" />
    <limit lower="0" upper="1.7" effort="1" velocity="0.5" />
  </joint>

  <joint name="L_index_intermediate_joint" type="revolute">
    <origin xyz="-0.0024229 -0.032041 -0.001" rpy="0 0 0" />
    <parent link="L_index_proximal" />
    <child link="L_index_intermediate" />
    <axis xyz="0 0 -1" />
    <limit lower="0" upper="1.7" effort="1" velocity="0.5" />
    <mimic joint="L_index_proximal_joint" multiplier="1" offset="0" />
  </joint>



  <joint name="L_index_tip_joint" type="fixed">
    <parent link="L_index_intermediate" />
    <child link="L_index_tip" />
    <origin rpy="0 0 0" xyz="-0.005 -0.04 -0.004" />
  </joint>



  <joint name="L_middle_proximal_joint" type="revolute">
    <origin xyz="0.01295 0.00028533 -0.1371" rpy="1.5708 0 1.5708" />
    <parent link="L_hand_base_link" />
    <child link="L_middle_proximal" />
    <axis xyz="0 0 -1" />
    <limit lower="0" upper="1.7" effort="1" velocity="0.5" />
  </joint>

  <joint name="L_middle_intermediate_joint" type="revolute">
    <origin xyz="-0.0024229 -0.032041 -0.001" rpy="0 0 0" />
    <parent link="L_middle_proximal" />
    <child link="L_middle_intermediate" />
    <axis xyz="0 0 -1" />
    <limit lower="0" upper="1.7" effort="1" velocity="0.5" />
    <mimic joint="L_middle_proximal_joint" multiplier="1" offset="0" />
  </joint>


  <joint name="L_middle_tip_joint" type="fixed">
    <parent link="L_middle_intermediate" />
    <child link="L_middle_tip" />
    <origin rpy="0 0 0" xyz="-0.005 -0.045 -0.004" />
  </joint>



  <joint name="L_ring_proximal_joint" type="revolute">
    <origin xyz="-0.0062872 0.00028533 -0.13691" rpy="1.5708 0.05236 1.5708" />
    <parent link="L_hand_base_link" />
    <child link="L_ring_proximal" />
    <axis xyz="0 0 -1" />
    <limit lower="0" upper="1.7" effort="1" velocity="0.5" />
  </joint>

  <joint name="L_ring_intermediate_joint" type="revolute">
    <origin xyz="-0.0024229 -0.032041 -0.001" rpy="0 0 0" />
    <parent link="L_ring_proximal" />
    <child link="L_ring_intermediate" />
    <axis xyz="0 0 -1" />
    <limit lower="0" upper="1.7" effort="1" velocity="0.5" />
    <mimic joint="L_ring_proximal_joint" multiplier="1" offset="0" />
  </joint>



  <joint name="L_ring_tip_joint" type="fixed">
    <parent link="L_ring_intermediate" />
    <child link="L_ring_tip" />
    <origin rpy="0 0 0" xyz="-0.002 -0.04 -0.004" />
  </joint>



  <joint name="L_pinky_proximal_joint" type="revolute">
    <origin xyz="-0.025488 0.00028533 -0.13571" rpy="1.5708 0.10472 1.5708" />
    <parent link="L_hand_base_link" />
    <child link="L_pinky_proximal" />
    <axis xyz="0 0 -1" />
    <limit lower="0" upper="1.7" effort="1" velocity="0.5" />
  </joint>

  <joint name="L_pinky_intermediate_joint" type="revolute">
    <origin xyz="-0.0024229 -0.032041 -0.001" rpy="0 0 0" />
    <parent link="L_pinky_proximal" />
    <child link="L_pinky_intermediate" />
    <axis xyz="0 0 -1" />
    <limit lower="0" upper="1.7" effort="1" velocity="0.5" />
    <mimic joint="L_pinky_proximal_joint" multiplier="1" offset="0" />
  </joint>


  <joint name="L_pinky_tip_joint" type="fixed">
    <parent link="L_pinky_intermediate" />
    <child link="L_pinky_tip" />
    <origin rpy="0 0 0" xyz="-0.002 -0.032 -0.004" />
  </joint>

<joint name="L_hand_base_joint" type="fixed"><parent link="left_end_effector_link" /><child link="L_hand_base_link" /><origin rpy="0 0 0" xyz="0 0 0" /></joint><link name="R_hand_base_link">
    <inertial>
      <origin xyz="-0.0025264 -0.066047 0.0019598" rpy="0 0 0" />
      <mass value="0.14143" />
      <inertia ixx="0.00012281" ixy="2.1711E-06" ixz="1.7709E-06" iyy="8.3832E-05" iyz="-1.6551E-06" izz="7.6663E-05" />
    </inertial>
    <visual>
      <origin xyz="0 0 0" rpy="1.570796 0 -1.570796" />
      <geometry>
        <mesh filename="../meshes/inspire_hand/base_link_r.STL" />
      </geometry>
      <material name="">
        <color rgba="1 1 1 1" />
      </material>
    </visual>
  </link>

  <link name="R_hand_wrist_link">
  </link>
  <link name="R_thumb_proximal_base">
    <inertial>
      <origin xyz="-0.0048064 0.0009382 -0.00757" rpy="0 0 0" />
      <mass value="0.0018869" />
      <inertia ixx="5.816E-08" ixy="1.4539E-08" ixz="4.491E-09" iyy="7.9161E-08" iyz="-1.8727E-09" izz="6.7433E-08" />
    </inertial>
    <visual>
      <origin xyz="0 0 0" rpy="0 0 0" />
      <geometry>
        <mesh filename="../meshes/inspire_hand/Link11_r.STL" />
      </geometry>
      <material name="">
        <color rgba="1 1 1 1" />
      </material>
    </visual>
  </link>

  <link name="R_thumb_proximal">
    <inertial>
      <origin xyz="0.021932 0.012785 -0.0080386" rpy="0 0 0" />
      <mass value="0.0066075" />
      <inertia ixx="1.5686E-06" ixy="-7.8296E-07" ixz="8.9143E-10" iyy="1.7353E-06" iyz="-1.0191E-09" izz="2.786E-06" />
    </inertial>
    <visual>
      <origin xyz="0 0 0" rpy="0 0 0" />
      <geometry>
        <mesh filename="../meshes/inspire_hand/Link12_r.STL" />
      </geometry>
      <material name="">
        <color rgba="1 1 1 1" />
      </material>
    </visual>
  </link>

  <link name="R_thumb_intermediate">
    <inertial>
      <origin xyz="0.0095544 -0.0016282 -0.0071997" rpy="0 0 0" />
      <mass value="0.0037847" />
      <inertia ixx="3.6981E-07" ixy="-9.8581E-08" ixz="-4.7469E-12" iyy="3.2394E-07" iyz="1.0939E-12" izz="4.6531E-07" />
    </inertial>
    <visual>
      <origin xyz="0 0 0" rpy="0 0 0" />
      <geometry>
        <mesh filename="../meshes/inspire_hand/Link13_r.STL" />
      </geometry>
      <material name="">
        <color rgba="1 1 1 1" />
      </material>
    </visual>
  </link>

  <link name="R_thumb_distal">
    <inertial>
      <origin xyz="0.0092888 0.0049529 -0.0060033" rpy="0 0 0" />
      <mass value="0.0033441" />
      <inertia ixx="1.3632E-07" ixy="-5.6788E-08" ixz="-9.2764E-11" iyy="1.4052E-07" iyz="-1.2283E-10" izz="2.0026E-07" />
    </inertial>
    <visual>
      <origin xyz="0 0 0" rpy="0 0 0" />
      <geometry>
        <mesh filename="../meshes/inspire_hand/Link14_r.STL" />
      </geometry>
      <material name="">
        <color rgba="1 1 1 1" />
      </material>
    </visual>
  </link>

  <link name="R_thumb_tip">
    <visual>
      <origin xyz="0 0 0" rpy="0 0 0" />
      <geometry>
        <sphere radius="0.005" />
      </geometry>
      <material name="green">
        <color rgba="0 1 0 1" />
      </material>
    </visual>
  </link>
  <link name="R_index_proximal">
    <inertial>
      <origin xyz="0.0012259 0.011942 -0.0060001" rpy="0 0 0" />
      <mass value="0.0042403" />
      <inertia ixx="6.6232E-07" ixy="-1.5775E-08" ixz="1.8515E-12" iyy="2.1146E-07" iyz="-5.0828E-12" izz="6.9398E-07" />
    </inertial>
    <visual>
      <origin xyz="0 0 0" rpy="0 0 0" />
      <geometry>
        <mesh filename="../meshes/inspire_hand/Link15_r.STL" />
      </geometry>
      <material name="">
        <color rgba="1 1 1 1" />
      </material>
    </visual>
  </link>

  <link name="R_index_intermediate">
    <inertial>
      <origin xyz="0.0019697 0.019589 -0.005" rpy="0 0 0" />
      <mass value="0.0045683" />
      <inertia ixx="7.6111E-07" ixy="8.7637E-08" ixz="-3.7751E-13" iyy="9.6076E-08" iyz="9.9444E-13" izz="7.8179E-07" />
    </inertial>
    <visual>
      <origin xyz="0 0 0" rpy="0 0 0" />
      <geometry>
        <mesh filename="../meshes/inspire_hand/Link16_r.STL" />
      </geometry>
      <material name="">
        <color rgba="1 1 1 1" />
      </material>
    </visual>
  </link>

  <link name="R_index_tip">
    <visual>
      <origin xyz="0 0 0" rpy="0 0 0" />
      <geometry>
        <sphere radius="0.005" />
      </geometry>
      <material name="green">
        <color rgba="0 1 0 1" />
      </material>
    </visual>
  </link>
  <link name="R_middle_proximal">
    <inertial>
      <origin xyz="0.001297 0.011934 -0.0060001" rpy="0 0 0" />
      <mass value="0.0042403" />
      <inertia ixx="6.6211E-07" ixy="-1.8461E-08" ixz="1.8002E-12" iyy="2.1167E-07" iyz="-6.6808E-12" izz="6.9397E-07" />
    </inertial>
    <visual>
      <origin xyz="0 0 0" rpy="0 0 0" />
      <geometry>
        <mesh filename="../meshes/inspire_hand/Link17_r.STL" />
      </geometry>
      <material name="">
        <color rgba="1 1 1 1" />
      </material>
    </visual>
  </link>

  <link name="R_middle_intermediate">
    <inertial>
      <origin xyz="0.001921 0.020796 -0.005" rpy="0 0 0" />
      <mass value="0.0050396" />
      <inertia ixx="9.5822E-07" ixy="1.1425E-07" ixz="-2.4791E-12" iyy="1.0646E-07" iyz="5.9173E-12" izz="9.8384E-07" />
    </inertial>
    <visual>
      <origin xyz="0 0 0" rpy="0 0 0" />
      <geometry>
        <mesh filename="../meshes/inspire_hand/Link18_r.STL" />
      </geometry>
      <material name="">
        <color rgba="1 1 1 1" />
      </material>
    </visual>
  </link>

  <link name="R_middle_tip">
    <visual>
      <origin xyz="0 0 0" rpy="0 0 0" />
      <geometry>
        <sphere radius="0.005" />
      </geometry>
      <material name="green">
        <color rgba="0 1 0 1" />
      </material>
    </visual>
  </link>
  <link name="R_ring_proximal">
    <inertial>
      <origin xyz="0.001297 0.011934 -0.0060002" rpy="0 0 0" />
      <mass value="0.0042403" />
      <inertia ixx="6.6211E-07" ixy="-1.8461E-08" ixz="1.5793E-12" iyy="2.1167E-07" iyz="-6.6868E-12" izz="6.9397E-07" />
    </inertial>
    <visual>
      <origin xyz="0 0 0" rpy="0 0 0" />
      <geometry>
        <mesh filename="../meshes/inspire_hand/Link19_r.STL" />
      </geometry>
      <material name="">
        <color rgba="1 1 1 1" />
      </material>
    </visual>
  </link>

  <link name="R_ring_intermediate">
    <inertial>
      <origin xyz="0.0021753 0.019567 -0.005" rpy="0 0 0" />
      <mass value="0.0045683" />
      <inertia ixx="7.6286E-07" ixy="8.0635E-08" ixz="-6.1562E-13" iyy="9.431E-08" iyz="5.8619E-13" izz="7.8177E-07" />
    </inertial>
    <visual>
      <origin xyz="0 0 0" rpy="0 0 0" />
      <geometry>
        <mesh filename="../meshes/inspire_hand/Link20_r.STL" />
      </geometry>
      <material name="">
        <color rgba="1 1 1 1" />
      </material>
    </visual>
  </link>

  <link name="R_ring_tip">
    <visual>
      <origin xyz="0 0 0" rpy="0 0 0" />
      <geometry>
        <sphere radius="0.005" />
      </geometry>
      <material name="green">
        <color rgba="0 1 0 1" />
      </material>
    </visual>
  </link>
  <link name="R_pinky_proximal">
    <inertial>
      <origin xyz="0.001297 0.011934 -0.0060001" rpy="0 0 0" />
      <mass value="0.0042403" />
      <inertia ixx="6.6211E-07" ixy="-1.8461E-08" ixz="1.6907E-12" iyy="2.1167E-07" iyz="-6.9334E-12" izz="6.9397E-07" />
    </inertial>
    <visual>
      <origin xyz="0 0 0" rpy="0 0 0" />
      <geometry>
        <mesh filename="../meshes/inspire_hand/Link21_r.STL" />
      </geometry>
      <material name="">
        <color rgba="1 1 1 1" />
      </material>
    </visual>
  </link>

  <link name="R_pinky_intermediate">
    <inertial>
      <origin xyz="0.0024748 0.016203 -0.0050031" rpy="0 0 0" />
      <mass value="0.0035996" />
      <inertia ixx="4.3913E-07" ixy="4.1418E-08" ixz="3.7168E-11" iyy="7.0247E-08" iyz="5.8613E-11" izz="4.4867E-07" />
    </inertial>
    <visual>
      <origin xyz="0 0 0" rpy="0 0 0" />
      <geometry>
        <mesh filename="../meshes/inspire_hand/Link22_r.STL" />
      </geometry>
      <material name="">
        <color rgba="1 1 1 1" />
      </material>
    </visual>
  </link>

  <link name="R_pinky_tip">
    <visual>
      <origin xyz="0 0 0" rpy="0 0 0" />
      <geometry>
        <sphere radius="0.005" />
      </geometry>
      <material name="green">
        <color rgba="0 1 0 1" />
      </material>
    </visual>
  </link>
  <joint name="R_hand_wrist_joint" type="fixed">
    <origin xyz="0 0 0" rpy="0 0 0" />
    <parent link="R_hand_base_link" />
    <child link="R_hand_wrist_link" />
    <axis xyz="0 0 0" />
  </joint>


  <joint name="R_thumb_proximal_yaw_joint" type="revolute">
    <origin xyz="0.02045 0.01696 -0.0691" rpy="0 3.1416 0" />
    <parent link="R_hand_base_link" />
    <child link="R_thumb_proximal_base" />
    <axis xyz="0 0 -1" />
    <limit lower="-0.1" upper="1.3" effort="1" velocity="0.5" />
  </joint>

  <joint name="R_thumb_proximal_pitch_joint" type="revolute">
    <origin xyz="-0.0088099 0.010892 -0.00925" rpy="1.5708 0 2.8587" />
    <parent link="R_thumb_proximal_base" />
    <child link="R_thumb_proximal" />
    <axis xyz="0 0 1" />
    <limit lower="-0.1" upper="0.6" effort="1" velocity="0.5" />
  </joint>

  <joint name="R_thumb_intermediate_joint" type="revolute">
    <origin xyz="0.04407 0.034553 -0.0008" rpy="0 0 0" />
    <parent link="R_thumb_proximal" />
    <child link="R_thumb_intermediate" />
    <axis xyz="0 0 1" />
    <limit lower="0" upper="0.8" effort="1" velocity="0.5" />
    <mimic joint="R_thumb_proximal_pitch_joint" multiplier="1.6" offset="0" />
  </joint>

  <joint name="R_thumb_distal_joint" type="revolute">
    <origin xyz="0.020248 0.010156 -0.0012" rpy="0 0 0" />
    <parent link="R_thumb_intermediate" />
    <child link="R_thumb_distal" />
    <axis xyz="0 0 1" />
    <limit lower="0" upper="1.2" effort="1" velocity="0.5" />
    <mimic joint="R_thumb_proximal_pitch_joint" multiplier="2.4" offset="0" />
  </joint>


  <joint name="R_thumb_tip_joint" type="fixed">
    <parent link="R_thumb_distal" />
    <child link="R_thumb_tip" />
    <origin rpy="0 0 0" xyz="0.015 0.013 -0.004" />
  </joint>



  <joint name="R_index_proximal_joint" type="revolute">
    <origin xyz="0.032268 0.00028533 -0.13653" rpy="-1.5359 0 -1.5708" />
    <parent link="R_hand_base_link" />
    <child link="R_index_proximal" />
    <axis xyz="0 0 1" />
    <limit lower="0" upper="1.7" effort="1" velocity="0.5" />
  </joint>

  <joint name="R_index_intermediate_joint" type="revolute">
    <origin xyz="-0.0026138 0.032026 -0.001" rpy="0 0 0" />
    <parent link="R_index_proximal" />
    <child link="R_index_intermediate" />
    <axis xyz="0 0 1" />
    <limit lower="0" upper="1.7" effort="1" velocity="0.5" />
    <mimic joint="R_index_proximal_joint" multiplier="1" offset="0" />
  </joint>



  <joint name="R_index_tip_joint" type="fixed">
    <parent link="R_index_intermediate" />
    <child link="R_index_tip" />
    <origin rpy="0 0 0" xyz="-0.005 0.04 -0.004" />
  </joint>




  <joint name="R_middle_proximal_joint" type="revolute">
    <origin xyz="0.01295 0.00028533 -0.1371" rpy="-1.5708 0 -1.5708" />
    <parent link="R_hand_base_link" />
    <child link="R_middle_proximal" />
    <axis xyz="0 0 1" />
    <limit lower="0" upper="1.7" effort="1" velocity="0.5" />
  </joint>

  <joint name="R_middle_intermediate_joint" type="revolute">
    <origin xyz="-0.0024229 0.032041 -0.001" rpy="0 0 0" />
    <parent link="R_middle_proximal" />
    <child link="R_middle_intermediate" />
    <axis xyz="0 0 1" />
    <limit lower="0" upper="1.7" effort="1" velocity="0.5" />
    <mimic joint="R_middle_proximal_joint" multiplier="1" offset="0" />
  </joint>


  <joint name="R_middle_tip_joint" type="fixed">
    <parent link="R_middle_intermediate" />
    <child link="R_middle_tip" />
    <origin rpy="0 0 0" xyz="-0.005 0.045 -0.004" />
  </joint>



  <joint name="R_ring_proximal_joint" type="revolute">
    <origin xyz="-0.0062872 0.00028533 -0.13691" rpy="-1.6232 0 -1.5708" />
    <parent link="R_hand_base_link" />
    <child link="R_ring_proximal" />
    <axis xyz="0 0 1" />
    <limit lower="0" upper="1.7" effort="1" velocity="0.5" />
  </joint>

  <joint name="R_ring_intermediate_joint" type="revolute">
    <origin xyz="-0.0024229 0.032041 -0.001" rpy="0 0 0" />
    <parent link="R_ring_proximal" />
    <child link="R_ring_intermediate" />
    <axis xyz="0 0 1" />
    <limit lower="0" upper="1.7" effort="1" velocity="0.5" />
    <mimic joint="R_ring_proximal_joint" multiplier="1" offset="0" />
  </joint>


  <joint name="R_ring_tip_joint" type="fixed">
    <parent link="R_ring_intermediate" />
    <child link="R_ring_tip" />
    <origin rpy="0 0 0" xyz="-0.002 0.04 -0.004" />
  </joint>



  <joint name="R_pinky_proximal_joint" type="revolute">
    <origin xyz="-0.025488 0.00028533 -0.13571" rpy="-1.6739 0 -1.5708" />
    <parent link="R_hand_base_link" />
    <child link="R_pinky_proximal" />
    <axis xyz="0 0 1" />
    <limit lower="0" upper="1.7" effort="1" velocity="0.5" />
  </joint>

  <joint name="R_pinky_intermediate_joint" type="revolute">
    <origin xyz="-0.0024229 0.032041 -0.001" rpy="0 0 0" />
    <parent link="R_pinky_proximal" />
    <child link="R_pinky_intermediate" />
    <axis xyz="0 0 1" />
    <limit lower="0" upper="1.7" effort="1" velocity="0.5" />
    <mimic joint="R_pinky_proximal_joint" multiplier="1" offset="0" />
  </joint>


  <joint name="R_pinky_tip_joint" type="fixed">
    <parent link="R_pinky_intermediate" />
    <child link="R_pinky_tip" />
    <origin rpy="0 0 0" xyz="-0.002 0.032 -0.004" />
  </joint>

<joint name="R_hand_base_joint" type="fixed"><parent link="right_end_effector_link" /><child link="R_hand_base_link" /><origin rpy="0 0 0" xyz="0 0 0" /></joint></robot>