<?xml version="1.0" encoding="utf-8"?>
<robot name="svh">
  <link name="base_link"/>
  <joint name="root_joint" type="fixed">
    <parent link="base_link"/>
    <child link="right_hand_base_link"/>
    <origin rpy="0 0 -1.57079" xyz="0 0 0"/>
  </joint>
  <link name="right_hand_base_link">
    <origin rpy="0 0 0" xyz="0 0 0"/>
    <visual>
      <origin rpy="0 0 0" xyz="0 0 -0.032"/>
      <geometry>
        <mesh filename="meshes/visual/base10.obj"/>
      </geometry>
    </visual>
    <collision>
      <origin rpy="0 0 0" xyz="0 0 -0.009"/>
      <geometry>
        <cylinder radius="0.045" length="0.045"/>
      </geometry>
    </collision>
  </link>
  <!-- LENGTH NOT FOUND IN DATASHEET! GUESSED!!! -->
  <link name="right_hand_e1">
    <visual>
      <origin rpy="0 0 0" xyz="0 0.01313 0"/>
      <geometry>
        <mesh filename="meshes/visual/h10.obj" scale="1 1 1"/>
      </geometry>
    </visual>
    <collision>
      <origin rpy="0 0 0" xyz="0 0.01313 0.013"/>
      <geometry>
        <box size="0.05 0.05 0.026"/>
      </geometry>
    </collision>
    <collision>
      <origin rpy="0 0 0" xyz="0.00573 0.0035 0.05747"/>
      <geometry>
        <box size="0.0584 0.038 0.0641"/>
      </geometry>
    </collision>
    <collision>
      <origin rpy="0 0 0" xyz="0.01 0.0035 0.096"/>
      <geometry>
        <box size="0.042 0.038 0.015"/>
      </geometry>
    </collision>
  </link>
  <!-- LENGTH NOT FOUND IN DATASHEET! GUESSED!!! -->
  <link name="right_hand_e2">
    <visual>
      <origin xyz="-0.0007 0 -0.01002"/>
      <geometry>
        <mesh filename="meshes/visual/h11.obj" scale="1 1 1"/>
      </geometry>
    </visual>
    <collision>
      <origin rpy="0 0 0" xyz="0.016 0 0.02"/>
      <geometry>
        <box size="0.0246 0.035 0.0564"/>
      </geometry>
    </collision>
    <collision>
      <origin rpy="0 0 0" xyz="0.0032 -0.0083 0.048"/>
      <geometry>
        <box size="0.012 0.018 0.021"/>
      </geometry>
    </collision>
  </link>
  <!-- THUMB LINKS -->
  <link name="RightHandThumb1_link_1">
    <visual>
      <origin xyz="0 0 0.02442"/>
      <geometry>
        <mesh filename="meshes/visual/d10.obj" scale="1 1 1"/>
      </geometry>
    </visual>
    <collision>
      <origin xyz="0 0 0.02842"/>
      <geometry>
        <box size="0.024 0.0188 0.008"/>
      </geometry>
    </collision>
    <collision>
      <origin xyz="0.0125 0.0 0.04292"/>
      <geometry>
        <box size="0.006 0.024 0.033"/>
      </geometry>
    </collision>
    <collision>
      <origin xyz="-0.0125 0.0 0.04292"/>
      <geometry>
        <box size="0.006 0.024 0.033"/>
      </geometry>
    </collision>
  </link>
  <link name="RightHandThumb1_link_2">
    <visual>
      <geometry>
        <mesh filename="meshes/visual/d11.obj" scale="1 1 1"/>
      </geometry>
    </visual>
    <collision>
      <geometry>
        <mesh filename="meshes/collision/d11.obj" scale="1 1 1"/>
      </geometry>
    </collision>
  </link>
  <link name="RightHandThumb2_link_0">
    <visual>
      <geometry>
        <mesh filename="meshes/visual/d12.obj" scale="1 1 1"/>
      </geometry>
    </visual>
    <collision>
      <geometry>
        <mesh filename="meshes/collision/d12.obj" scale="1 1 1"/>
      </geometry>
    </collision>
  </link>
  <link name="RightHandThumb3_link_0">
    <inertial>
      <origin rpy="0 0 0" xyz="0.007 0.000 0.000"/>
      <mass value="0.02"/>
      <inertia ixx="1e-5" ixy="0.0" ixz="0.0" iyy="2e-5" iyz="0.0" izz="2e-5"/>
    </inertial>
    <visual>
      <geometry>
        <mesh filename="meshes/visual/d13.obj" scale="1 1 1"/>
      </geometry>
    </visual>
    <collision>
      <geometry>
        <mesh filename="meshes/collision/d13.obj" scale="1 1 1"/>
      </geometry>
    </collision>
  </link>
  <!-- INDEX FINGER LINKS -->
  <link name="RightHandIndex1_link_0">
    <visual>
      <origin xyz="0 0 0.01321"/>
      <geometry>
        <mesh filename="meshes/visual/f10_f20.obj"/>
      </geometry>
    </visual>
    <collision>
      <origin xyz="0 0 0.00121"/>
      <geometry>
        <sphere radius="0.01"/>
      </geometry>
    </collision>
  </link>
  <link name="RightHandIndex1_link_1">
    <visual>
      <geometry>
        <mesh filename="meshes/visual/f11.obj"/>
      </geometry>
    </visual>
    <collision>
      <geometry>
        <mesh filename="meshes/collision/f11.obj" scale="1 1 1"/>
      </geometry>
    </collision>
  </link>
  <link name="RightHandIndex2_link_0">
    <inertial>
      <origin rpy="0 0 0" xyz="0.01 0.000 0.000"/>
      <mass value="0.024"/>
      <inertia ixx="9e-7" ixy="0.0" ixz="0.0" iyy="3e-6" iyz="0.0" izz="2e-6"/>
    </inertial>
    <visual>
      <geometry>
        <mesh filename="meshes/visual/f12.obj"/>
      </geometry>
    </visual>
    <collision>
      <geometry>
        <mesh filename="meshes/collision/f12.obj"/>
      </geometry>
    </collision>
  </link>
  <link name="RightHandIndex3_link_0">
    <inertial>
      <origin rpy="0 0 0" xyz="0.007 0.000 0.000"/>
      <mass value="0.02"/>
      <inertia ixx="1e-5" ixy="0.0" ixz="0.0" iyy="2e-5" iyz="0.0" izz="2e-5"/>
    </inertial>
    <visual>
      <geometry>
        <mesh filename="meshes/visual/finger_tip.obj"/>
      </geometry>
    </visual>
    <collision>
      <geometry>
        <mesh filename="meshes/collision/finger_tip.obj" scale="1 1 1"/>
      </geometry>
    </collision>
  </link>
  <!-- MIDDLE FINGER LINKS -->
  <link name="RightHandMiddle1_link_1">
    <visual>
      <origin xyz="0 0 0.01321"/>
      <geometry>
        <mesh filename="meshes/visual/f10_f20.obj"/>
      </geometry>
    </visual>
    <collision>
      <origin xyz="0 0 0.00321"/>
      <geometry>
        <sphere radius="0.01"/>
      </geometry>
    </collision>
  </link>
  <link name="RightHandMiddle1_link_0">
    <visual>
      <geometry>
        <mesh filename="meshes/visual/f21.obj"/>
      </geometry>
    </visual>
    <collision>
      <geometry>
        <mesh filename="meshes/collision/f21.obj" scale="1 1 1"/>
      </geometry>
    </collision>
  </link>
  <link name="RightHandMiddle2_link_0">
    <visual>
      <geometry>
        <mesh filename="meshes/visual/f22_f32.obj"/>
      </geometry>
    </visual>
    <collision>
      <geometry>
        <mesh filename="meshes/collision/f22_f32.obj" scale="1 1 1"/>
      </geometry>
    </collision>
  </link>
  <link name="RightHandMiddle3_link_0">
    <inertial>
      <origin rpy="0 0 0" xyz="0.007 0.000 0.000"/>
      <mass value="0.02"/>
      <inertia ixx="1e-5" ixy="0.0" ixz="0.0" iyy="2e-5" iyz="0.0" izz="2e-5"/>
    </inertial>
    <visual>
      <geometry>
        <mesh filename="meshes/visual/finger_tip.obj"/>
      </geometry>
    </visual>
    <collision>
      <geometry>
        <mesh filename="meshes/collision/finger_tip.obj" scale="1 1 1"/>
      </geometry>
    </collision>
  </link>
  <!-- RING FINGER LINKS -->
  <link name="RightHandRing1_link_0">
    <visual>
      <origin xyz="0 0 -0.01321"/>
      <geometry>
        <mesh filename="meshes/visual/f30_f40.obj"/>
      </geometry>
    </visual>
    <collision>
      <origin xyz="0 0 -0.00321"/>
      <geometry>
        <sphere radius="0.01"/>
      </geometry>
    </collision>
  </link>
  <link name="RightHandRing1_link_1">
    <visual>
      <geometry>
        <mesh filename="meshes/visual/f31.obj"/>
      </geometry>
    </visual>
    <collision>
      <geometry>
        <mesh filename="meshes/collision/f31.obj" scale="1 1 1"/>
      </geometry>
    </collision>
  </link>
  <link name="RightHandRing2_link_0">
    <visual>
      <geometry>
        <mesh filename="meshes/visual/f22_f32.obj"/>
      </geometry>
    </visual>
    <collision>
      <geometry>
        <mesh filename="meshes/collision/f22_f32.obj" scale="1 1 1"/>
      </geometry>
    </collision>
  </link>
  <link name="RightHandRing3_link_0">
    <inertial>
      <origin rpy="0 0 0" xyz="0.007 0.000 0.000"/>
      <mass value="0.02"/>
      <inertia ixx="1e-5" ixy="0.0" ixz="0.0" iyy="2e-5" iyz="0.0" izz="2e-5"/>
    </inertial>
    <visual>
      <geometry>
        <mesh filename="meshes/visual/finger_tip.obj"/>
      </geometry>
    </visual>
    <collision>
      <geometry>
        <mesh filename="meshes/collision/finger_tip.obj" scale="1 1 1"/>
      </geometry>
    </collision>
  </link>
  <!-- LITTLE FINGER LINKS -->
  <link name="RightHandPinky1_link_0">
    <visual>
      <origin xyz="0 0 -0.01321"/>
      <geometry>
        <mesh filename="meshes/visual/f30_f40.obj"/>
      </geometry>
    </visual>
    <collision>
      <origin xyz="0 0 -0.00321"/>
      <geometry>
        <sphere radius="0.01"/>
      </geometry>
    </collision>
  </link>
  <link name="RightHandPinky1_link_1">
    <visual>
      <geometry>
        <mesh filename="meshes/visual/f41.obj"/>
      </geometry>
    </visual>
    <collision>
      <geometry>
        <mesh filename="meshes/collision/f41.obj"/>
      </geometry>
    </collision>
  </link>
  <link name="RightHandPinky2_link_0">
    <inertial>
      <origin rpy="0 0 0" xyz="0.007 0.000 0.000"/>
      <mass value="0.02"/>
      <inertia ixx="8e-7" ixy="0.0" ixz="0.0" iyy="2e-6" iyz="0.0" izz="2e-6"/>
    </inertial>
    <visual>
      <geometry>
        <mesh filename="meshes/visual/f42.obj"/>
      </geometry>
    </visual>
    <collision>
      <geometry>
        <mesh filename="meshes/collision/f42.obj"/>
      </geometry>
    </collision>
  </link>
  <link name="RightHandPinky3_link_0">
    <inertial>
      <origin rpy="0 0 0" xyz="0.007 0.000 0.000"/>
      <mass value="0.02"/>
      <inertia ixx="1e-5" ixy="0.0" ixz="0.0" iyy="2e-5" iyz="0.0" izz="2e-5"/>
    </inertial>
    <visual>
      <geometry>
        <mesh filename="meshes/visual/finger_tip.obj"/>
      </geometry>
    </visual>
    <collision>
      <geometry>
        <mesh filename="meshes/collision/finger_tip.obj"/>
      </geometry>
    </collision>
  </link>
  <joint name="RightHandThumb1_joint_2" type="revolute">
    <parent link="RightHandThumb1_link_1"/>
    <child link="RightHandThumb1_link_2"/>
    <limit effort="1000.0" lower="-0.66374" upper="0.97039"  velocity="1"/>
    <origin rpy="1.570795 2.179043 1.465802" xyz="0 0 0"/>
    <axis xyz="0 0 1"/>
  </joint>
  <!-- BASE_LINE JOINTS -->
  <joint name="RightHandThumb1_joint_1" type="revolute">
    <parent link="right_hand_e1"/>
    <child link="RightHandThumb1_link_1"/>
    <limit effort="1000.0" lower="-0.73303" upper="1.81863" velocity="1"/>
    <origin rpy="2.459798 2.603466 0.681787" xyz="-0.025812 0.015521 0.024096"/>
    <axis xyz="0 0 -1"/>
  </joint>
  <joint name="right_hand_f4" type="fixed">
    <parent link="right_hand_base_link"/>
    <child link="right_hand_e1"/>
    <origin rpy="0 0 0" xyz="0 0 0"/>
  </joint>
  <joint name="right_hand_j5" type="revolute">
    <parent link="right_hand_e1"/>
    <child link="right_hand_e2"/>
    <limit effort="1000.0" upper="0.0" lower="0" velocity="1"/>
    <origin rpy="0 0 0" xyz="0.0244 0 0.032061"/>
    <axis xyz="0 0 1"/>
    <mimic joint="RightHandThumb1_joint_1" multiplier="0.000000001" offset="0"/>
  </joint>
  <!-- THUMB JOINTS -->
  <joint name="RightHandThumb2_joint_0" type="revolute">
    <parent link="RightHandThumb1_link_2"/>
    <child link="RightHandThumb2_link_0"/>
    <limit effort="1000.0" upper="0.98506" lower="0" velocity="1"/>
    <origin rpy="1.593293 -1.461151 2.153218" xyz="0.017363 -0.024952 -0.000005"/>
    <axis xyz="0 0 1"/>
  </joint>
  <joint name="RightHandThumb3_joint_0" type="revolute">
    <parent link="RightHandThumb2_link_0"/>
    <child link="RightHandThumb3_link_0"/>
    <limit effort="1000.0" lower="0" upper="1.406" velocity="1"/>
    <origin rpy="0 0 0" xyz="-0.003067 0.027668 0.000048"/>
    <axis xyz="0 0 1"/>
  </joint>
  <!-- INDEX FINGER JOINTS -->
  <joint name="RightHandIndex2_joint_0" type="revolute">
    <parent link="RightHandIndex1_link_1"/>
    <child link="RightHandIndex2_link_0"/>
    <limit effort="1000.0" lower="0" upper="1.334" velocity="1"/>
    <origin rpy="1.5707964 3.141592 0" xyz="-0.033 0 0"/>
    <axis xyz="0 0 -1"/>
  </joint>
  <joint name="RightHandIndex1_joint_1" type="revolute">
    <parent link="RightHandIndex1_link_0"/>
    <child link="RightHandIndex1_link_1"/>
    <limit effort="1000.0" upper="0.436" lower="-0.61" velocity="1"/>
    <origin rpy="-1.5707 -3.141592 0" xyz="0 0 0"/>
    <axis xyz="0 0 -1"/>
  </joint>
  <!-- JOINT Finger_Spread in BASE_LINE section for better UX -->
  <joint name="RightHandIndex3_joint_0" type="revolute">
    <parent link="RightHandIndex2_link_0"/>
    <child link="RightHandIndex3_link_0"/>
    <limit effort="1000.0" lower="0" upper="1.394" velocity="1"/>
    <origin rpy="0 0 0" xyz="0.022 0 0"/>
    <axis xyz="0 0 -1"/>
  </joint>
  <!-- MIDDLE FINGER JOINTS -->
  <joint name="RightHandMiddle1_joint_0" type="revolute">
    <parent link="right_hand_e1"/>
    <child link="RightHandMiddle1_link_0"/>
    <limit effort="1000.0" lower="-0.52" upper="1.57" velocity="1"/>
    <origin rpy="0 -1.5707 0" xyz="0.003359 0.001478 0.094666"/>
    <axis xyz="0 0 1"/>
  </joint>
  <joint name="RightHandMiddle2_joint_0" type="revolute">
    <parent link="RightHandMiddle1_link_1"/>
    <child link="RightHandMiddle2_link_0"/>
    <limit effort="1000.0" lower="0" upper="1.334" velocity="1"/>
    <origin rpy="1.5707964 3.141592 0" xyz="-0.031735 0 0"/>
    <axis xyz="0 0 -1"/>
  </joint>
  <joint name="RightHandMiddle3_joint_0" type="revolute">
    <parent link="RightHandMiddle2_link_0"/>
    <child link="RightHandMiddle3_link_0"/>
    <limit effort="1000.0" lower="0" upper="1.334" velocity="1"/>
    <origin rpy="0 0 0" xyz="0.023274 0 0"/>
    <axis xyz="0 0 -1"/>
  </joint>
  <!-- RING FINGER JOINTS -->
  <joint name="RightHandRing1_joint_1" type="revolute">
    <parent link="RightHandRing1_link_0"/>
    <child link="RightHandRing1_link_1"/>
    <limit effort="1000.0" lower="-0.436" upper="0.174" velocity="1"/>
    <origin rpy="-1.5707 -3.141592 0" xyz="0 0 0"/>
    <axis xyz="0 0 -1"/>
  </joint>
  <joint name="RightHandRing2_joint_0" type="revolute">
    <parent link="RightHandRing1_link_1"/>
    <child link="RightHandRing2_link_0"/>
    <limit effort="1000.0" lower="0" upper="1.334" velocity="1"/>
    <origin rpy="1.5707 3.141592 0" xyz="-0.028843 0 0"/>
    <axis xyz="0 0 -1"/>
  </joint>
  <joint name="RightHandRing3_joint_0" type="revolute">
    <parent link="RightHandRing2_link_0"/>
    <child link="RightHandRing3_link_0"/>
    <limit effort="1000.0" lower="0" upper="1.395" velocity="1"/>
    <origin rpy="0 0 0" xyz="0.024786 0 0"/>
    <axis xyz="0 0 -1"/>
  </joint>
  <!-- PINKY JOINTS -->
  <joint name="RightHandPinky1_joint_1" type="revolute">
    <parent link="RightHandPinky1_link_0"/>
    <child link="RightHandPinky1_link_1"/>
    <limit effort="1000.0" lower="-0.7" upper="0.174" velocity="1"/>
    <origin rpy="-1.5707 -3.141592 0" xyz="0 0 0"/>
    <axis xyz="0 0 -1"/>
  </joint>
  <joint name="RightHandPinky2_joint_0" type="revolute">
    <parent link="RightHandPinky1_link_1"/>
    <child link="RightHandPinky2_link_0"/>
    <limit effort="1000.0" lower="0" upper="1.334" velocity="1"/>
    <origin rpy="1.5707 3.141592 0" xyz="-0.021112 0 0"/>
    <axis xyz="0 0 -1"/>
  </joint>
  <joint name="RightHandPinky3_joint_0" type="revolute">
    <parent link="RightHandPinky2_link_0"/>
    <child link="RightHandPinky3_link_0"/>
    <limit effort="1000.0" lower="0" upper="1.3971" velocity="1"/>
    <origin rpy="0 0 0" xyz="0.018945 0 0"/>
    <axis xyz="0 0 -1"/>
  </joint>
  <joint name="RightHandIndex1_joint_0" type="revolute">
    <parent link="right_hand_e1"/>
    <child link="RightHandIndex1_link_0"/>
    <limit effort="1000.0" upper="1.57" lower="-0.52" velocity="1"/>
    <origin rpy="0 -1.5707 0" xyz="-0.020685 0.005199 0.088103"/>
    <axis xyz="0 0 1"/>
  </joint>
  <joint name="RightHandMiddle1_joint_1" type="revolute">
    <parent link="RightHandMiddle1_link_0"/>
    <child link="RightHandMiddle1_link_1"/>
    <limit effort="1000.0" upper="0.436" lower="-0.61" velocity="1"/>
    <origin rpy="-1.5707 -3.141592 0" xyz="0 0 0"/>
    <axis xyz="0 0 -1"/>
  </joint>
  <joint name="RightHandRing1_joint_0" type="revolute">
    <parent link="right_hand_e2"/>
    <child link="RightHandRing1_link_0"/>
    <limit effort="1000.0" lower="-0.52" upper="1.57" velocity="1"/>
    <origin rpy="-1.5707 -1.5707 1.5707" xyz="0.002274 0.003956 0.049681"/>
    <axis xyz="0 0 1"/>
  </joint>
  <joint name="RightHandPinky1_joint_0" type="revolute">
    <parent link="right_hand_e2"/>
    <child link="RightHandPinky1_link_0"/>
    <limit effort="1000.0" lower="-0.52" upper="1.57" velocity="1"/>
    <origin rpy="-1.5707 -1.5707 1.5707" xyz="0.01881 0.009939 0.036732"/>
    <axis xyz="0 0 1"/>
  </joint>

  <link name="thtip"/>
  <link name="fftip"/>
  <link name="mftip"/>
  <link name="rftip"/>
  <link name="lftip"/>
  <joint name="thtip_joint" type="fixed">
    <parent link="RightHandThumb3_link_0"/>
    <child link="thtip"/>
    <origin rpy="0.00000 -0.00000 0.00000" xyz="-0.004005 0.036129 0.000063"/>
  </joint>
  <joint name="fftip_joint" type="fixed">
    <parent link="RightHandIndex3_link_0"/>
    <child link="fftip"/>
    <origin rpy="0.00000 -0.00000 0.00000" xyz="0.026 0.000 0.000"/>
    <axis xyz="0 0 -1"/>
  </joint>
  <joint name="mftip_joint" type="fixed">
    <parent link="RightHandMiddle3_link_0"/>
    <child link="mftip"/>
    <origin rpy="0.00000 -0.00000 0.00000" xyz="0.026116 0.000 0.000"/>
    <axis xyz="0 0 -1"/>
  </joint>
  <joint name="rftip_joint" type="fixed">
    <parent link="RightHandRing3_link_0"/>
    <child link="rftip"/>
    <origin rpy="0.00000 -0.00000 0.00000" xyz="0.025406 0.000 0.000"/>
    <axis xyz="0 0 -1"/>
  </joint>
  <joint name="lftip_joint" type="fixed">
    <parent link="RightHandPinky3_link_0"/>
    <child link="lftip"/>
    <origin rpy="0.00000 -0.00000 0.00000" xyz="0.02058 0.000 0.000"/>
    <axis xyz="0 0 -1"/>
  </joint>
</robot>
