<robot name="svh">
  <link name="base_link" />
  <joint name="root_joint" type="fixed">
    <parent link="base_link" />
    <child link="left_hand_base_link" />
    <origin rpy="-0.000000 0.000000 -1.570790" xyz="-0.000000 0.000000 0.000000" />
  </joint>
  <link name="left_hand_base_link">
    <origin rpy="-0.000000 0.000000 -0.000000" xyz="-0.000000 0.000000 0.000000" />
    <visual>
      <origin rpy="-0.000000 0.000000 -0.000000" xyz="-0.000000 0.000000 -0.032000" />
      <geometry>
        <mesh filename="meshes/visual/base10.obj" />
      </geometry>
    </visual>
    <collision>
      <origin rpy="-0.000000 0.000000 -0.000000" xyz="-0.000000 0.000000 -0.009000" />
      <geometry>
        <cylinder radius="0.045" length="0.045" />
      </geometry>
    </collision>
  </link>
  
  <link name="left_hand_e1">
    <visual>
      <origin rpy="-0.000000 0.000000 -0.000000" xyz="-0.000000 0.013130 0.000000" />
      <geometry>
        <mesh filename="meshes/visual/h10_left.obj" scale="1 1 1" />
      </geometry>
    </visual>
    <collision>
      <origin rpy="-0.000000 0.000000 -0.000000" xyz="-0.000000 0.013130 0.013000" />
      <geometry>
        <box size="0.05 0.05 0.026" />
      </geometry>
    </collision>
    <collision>
      <origin rpy="-0.000000 0.000000 -0.000000" xyz="-0.005730 0.003500 0.057470" />
      <geometry>
        <box size="0.0584 0.038 0.0641" />
      </geometry>
    </collision>
    <collision>
      <origin rpy="-0.000000 0.000000 -0.000000" xyz="-0.010000 0.003500 0.096000" />
      <geometry>
        <box size="0.042 0.038 0.015" />
      </geometry>
    </collision>
  </link>
  
  <link name="left_hand_e2">
    <visual>
      <origin xyz="0.000700 0.000000 -0.010020" />
      <geometry>
        <mesh filename="meshes/visual/h11_left.obj" scale="1 1 1" />
      </geometry>
    </visual>
    <collision>
      <origin rpy="-0.000000 0.000000 -0.000000" xyz="-0.016000 0.000000 0.020000" />
      <geometry>
        <box size="0.0246 0.035 0.0564" />
      </geometry>
    </collision>
    <collision>
      <origin rpy="-0.000000 0.000000 -0.000000" xyz="-0.003200 -0.008300 0.048000" />
      <geometry>
        <box size="0.012 0.018 0.021" />
      </geometry>
    </collision>
  </link>
  
  <link name="LeftHandThumb1_link_1">
    <visual>
      <origin xyz="-0.000000 0.000000 0.024420" />
      <geometry>
        <mesh filename="meshes/visual/d10_left.obj" scale="1 1 1" />
      </geometry>
    </visual>
    <collision>
      <origin xyz="-0.000000 0.000000 0.028420" />
      <geometry>
        <box size="0.024 0.0188 0.008" />
      </geometry>
    </collision>
    <collision>
      <origin xyz="-0.012500 0.000000 0.042920" />
      <geometry>
        <box size="0.006 0.024 0.033" />
      </geometry>
    </collision>
    <collision>
      <origin xyz="0.012500 0.000000 0.042920" />
      <geometry>
        <box size="0.006 0.024 0.033" />
      </geometry>
    </collision>
  </link>
  <link name="LeftHandThumb1_link_2">
    <visual>
      <geometry>
        <mesh filename="meshes/visual/d11_left.obj" scale="1 1 1" />
      </geometry>
    </visual>
    <collision>
      <geometry>
        <mesh filename="meshes/collision/d11_left.obj" scale="1 1 1" />
      </geometry>
    </collision>
  </link>
  <link name="LeftHandThumb2_link_0">
    <visual>
      <geometry>
        <mesh filename="meshes/visual/d12_left.obj" scale="1 1 1" />
      </geometry>
    </visual>
    <collision>
      <geometry>
        <mesh filename="meshes/collision/d12_left.obj" scale="1 1 1" />
      </geometry>
    </collision>
  </link>
  <link name="LeftHandThumb3_link_0">
    <inertial>
      <origin rpy="-0.000000 0.000000 -0.000000" xyz="-0.007000 0.000000 0.000000" />
      <mass value="0.02" />
      <inertia ixx="1e-5" ixy="0.0" ixz="0.0" iyy="2e-5" iyz="0.0" izz="2e-5" />
    </inertial>
    <visual>
      <geometry>
        <mesh filename="meshes/visual/d13_left.obj" scale="1 1 1" />
      </geometry>
    </visual>
    <collision>
      <geometry>
        <mesh filename="meshes/collision/d13_left.obj" scale="1 1 1" />
      </geometry>
    </collision>
  </link>
  
  <link name="LeftHandIndex1_link_0">
    <visual>
      <origin xyz="-0.000000 0.000000 0.013210" />
      <geometry>
        <mesh filename="meshes/visual/f10_f20.obj" />
      </geometry>
    </visual>
    <collision>
      <origin xyz="-0.000000 0.000000 0.001210" />
      <geometry>
        <sphere radius="0.01" />
      </geometry>
    </collision>
  </link>
  <link name="LeftHandIndex1_link_1">
    <visual>
      <geometry>
        <mesh filename="meshes/visual/f11.obj" />
      </geometry>
    </visual>
    <collision>
      <geometry>
        <mesh filename="meshes/collision/f11.obj" scale="1 1 1" />
      </geometry>
    </collision>
  </link>
  <link name="LeftHandIndex2_link_0">
    <inertial>
      <origin rpy="-0.000000 0.000000 -0.000000" xyz="-0.010000 0.000000 0.000000" />
      <mass value="0.024" />
      <inertia ixx="9e-7" ixy="0.0" ixz="0.0" iyy="3e-6" iyz="0.0" izz="2e-6" />
    </inertial>
    <visual>
      <geometry>
        <mesh filename="meshes/visual/f12.obj" />
      </geometry>
    </visual>
    <collision>
      <geometry>
        <mesh filename="meshes/collision/f12.obj" />
      </geometry>
    </collision>
  </link>
  <link name="LeftHandIndex3_link_0">
    <inertial>
      <origin rpy="-0.000000 0.000000 -0.000000" xyz="-0.007000 0.000000 0.000000" />
      <mass value="0.02" />
      <inertia ixx="1e-5" ixy="0.0" ixz="0.0" iyy="2e-5" iyz="0.0" izz="2e-5" />
    </inertial>
    <visual>
      <geometry>
        <mesh filename="meshes/visual/finger_tip.obj" />
      </geometry>
    </visual>
    <collision>
      <geometry>
        <mesh filename="meshes/collision/finger_tip.obj" scale="1 1 1" />
      </geometry>
    </collision>
  </link>
  
  <link name="LeftHandMiddle1_link_1">
    <visual>
      <origin xyz="-0.000000 0.000000 0.013210" />
      <geometry>
        <mesh filename="meshes/visual/f10_f20.obj" />
      </geometry>
    </visual>
    <collision>
      <origin xyz="-0.000000 0.000000 0.003210" />
      <geometry>
        <sphere radius="0.01" />
      </geometry>
    </collision>
  </link>
  <link name="LeftHandMiddle1_link_0">
    <visual>
      <geometry>
        <mesh filename="meshes/visual/f21.obj" />
      </geometry>
    </visual>
    <collision>
      <geometry>
        <mesh filename="meshes/collision/f21.obj" scale="1 1 1" />
      </geometry>
    </collision>
  </link>
  <link name="LeftHandMiddle2_link_0">
    <visual>
      <geometry>
        <mesh filename="meshes/visual/f22_f32.obj" />
      </geometry>
    </visual>
    <collision>
      <geometry>
        <mesh filename="meshes/collision/f22_f32.obj" scale="1 1 1" />
      </geometry>
    </collision>
  </link>
  <link name="LeftHandMiddle3_link_0">
    <inertial>
      <origin rpy="-0.000000 0.000000 -0.000000" xyz="-0.007000 0.000000 0.000000" />
      <mass value="0.02" />
      <inertia ixx="1e-5" ixy="0.0" ixz="0.0" iyy="2e-5" iyz="0.0" izz="2e-5" />
    </inertial>
    <visual>
      <geometry>
        <mesh filename="meshes/visual/finger_tip.obj" />
      </geometry>
    </visual>
    <collision>
      <geometry>
        <mesh filename="meshes/collision/finger_tip.obj" scale="1 1 1" />
      </geometry>
    </collision>
  </link>
  
  <link name="LeftHandRing1_link_0">
    <visual>
      <origin xyz="-0.000000 0.000000 -0.013210" />
      <geometry>
        <mesh filename="meshes/visual/f30_f40.obj" />
      </geometry>
    </visual>
    <collision>
      <origin xyz="-0.000000 0.000000 -0.003210" />
      <geometry>
        <sphere radius="0.01" />
      </geometry>
    </collision>
  </link>
  <link name="LeftHandRing1_link_1">
    <visual>
      <geometry>
        <mesh filename="meshes/visual/f31.obj" />
      </geometry>
    </visual>
    <collision>
      <geometry>
        <mesh filename="meshes/collision/f31.obj" scale="1 1 1" />
      </geometry>
    </collision>
  </link>
  <link name="LeftHandRing2_link_0">
    <visual>
      <geometry>
        <mesh filename="meshes/visual/f22_f32.obj" />
      </geometry>
    </visual>
    <collision>
      <geometry>
        <mesh filename="meshes/collision/f22_f32.obj" scale="1 1 1" />
      </geometry>
    </collision>
  </link>
  <link name="LeftHandRing3_link_0">
    <inertial>
      <origin rpy="-0.000000 0.000000 -0.000000" xyz="-0.007000 0.000000 0.000000" />
      <mass value="0.02" />
      <inertia ixx="1e-5" ixy="0.0" ixz="0.0" iyy="2e-5" iyz="0.0" izz="2e-5" />
    </inertial>
    <visual>
      <geometry>
        <mesh filename="meshes/visual/finger_tip.obj" />
      </geometry>
    </visual>
    <collision>
      <geometry>
        <mesh filename="meshes/collision/finger_tip.obj" scale="1 1 1" />
      </geometry>
    </collision>
  </link>
  
  <link name="LeftHandPinky1_link_0">
    <visual>
      <origin xyz="-0.000000 0.000000 -0.013210" />
      <geometry>
        <mesh filename="meshes/visual/f30_f40.obj" />
      </geometry>
    </visual>
    <collision>
      <origin xyz="-0.000000 0.000000 -0.003210" />
      <geometry>
        <sphere radius="0.01" />
      </geometry>
    </collision>
  </link>
  <link name="LeftHandPinky1_link_1">
    <visual>
      <geometry>
        <mesh filename="meshes/visual/f41.obj" />
      </geometry>
    </visual>
    <collision>
      <geometry>
        <mesh filename="meshes/collision/f41.obj" />
      </geometry>
    </collision>
  </link>
  <link name="LeftHandPinky2_link_0">
    <inertial>
      <origin rpy="-0.000000 0.000000 -0.000000" xyz="-0.007000 0.000000 0.000000" />
      <mass value="0.02" />
      <inertia ixx="8e-7" ixy="0.0" ixz="0.0" iyy="2e-6" iyz="0.0" izz="2e-6" />
    </inertial>
    <visual>
      <geometry>
        <mesh filename="meshes/visual/f42.obj" />
      </geometry>
    </visual>
    <collision>
      <geometry>
        <mesh filename="meshes/collision/f42.obj" />
      </geometry>
    </collision>
  </link>
  <link name="LeftHandPinky3_link_0">
    <inertial>
      <origin rpy="-0.000000 0.000000 -0.000000" xyz="-0.007000 0.000000 0.000000" />
      <mass value="0.02" />
      <inertia ixx="1e-5" ixy="0.0" ixz="0.0" iyy="2e-5" iyz="0.0" izz="2e-5" />
    </inertial>
    <visual>
      <geometry>
        <mesh filename="meshes/visual/finger_tip.obj" />
      </geometry>
    </visual>
    <collision>
      <geometry>
        <mesh filename="meshes/collision/finger_tip.obj" />
      </geometry>
    </collision>
  </link>
  <joint name="LeftHandThumb1_joint_2" type="revolute">
    <parent link="LeftHandThumb1_link_1" />
    <child link="LeftHandThumb1_link_2" />
    <limit effort="1000.0" lower="-0.66374" upper="0.97039" velocity="1" />
    <origin rpy="-1.570809 -0.699391 0.002499" xyz="-0.000000 0.000000 0.000000" />
    <axis xyz="-0.000000 0.000000 1.000000" />
  </joint>
  
  <joint name="LeftHandThumb1_joint_1" type="revolute">
    <parent link="left_hand_e1" />
    <child link="LeftHandThumb1_link_1" />
    <limit effort="1000.0" lower="-0.73303" upper="1.81863" velocity="1" />
    <origin rpy="0.59829044 -0.63200986 0.5955324" xyz="0.025812 0.015521 0.024096" />
    <axis xyz="-0.000000 0.000000 1.000000" />
  </joint>
  <joint name="left_hand_f4" type="fixed">
    <parent link="left_hand_base_link" />
    <child link="left_hand_e1" />
    <origin rpy="-0.000000 0.000000 -0.000000" xyz="-0.000000 0.000000 0.000000" />
  </joint>
  <joint name="left_hand_j5" type="revolute">
    <parent link="left_hand_e1" />
    <child link="left_hand_e2" />
    <limit effort="1000.0" upper="0.0" lower="0" velocity="1" />
    <origin rpy="-0.000000 0.000000 -0.000000" xyz="-0.024400 0.000000 0.032061" />
    <axis xyz="-0.000000 0.000000 1.000000" />
    <mimic joint="LeftHandThumb1_joint_1" multiplier="0.000000001" offset="0" />
  </joint>
  
  <joint name="LeftHandThumb2_joint_0" type="revolute">
    <parent link="LeftHandThumb1_link_2" />
    <child link="LeftHandThumb2_link_0" />
    <limit effort="1000.0" upper="0.98506" lower="0" velocity="1" />
    <origin rpy="1.573274 -0.003074 0.695892" xyz="0.023268 0.019562 0.000003" />
    <axis xyz="-0.000000 0.000000 1.000000" />
  </joint>
  <joint name="LeftHandThumb3_joint_0" type="revolute">
    <parent link="LeftHandThumb2_link_0" />
    <child link="LeftHandThumb3_link_0" />
    <limit effort="1000.0" lower="0" upper="1.406" velocity="1" />
    <origin rpy="-0.000000 0.000000 -0.000000" xyz="0.027837 -0.000065 -0.000050" />
    <axis xyz="-0.000000 0.000000 1.000000" />
  </joint>
  
  <joint name="LeftHandIndex2_joint_0" type="revolute">
    <parent link="LeftHandIndex1_link_1" />
    <child link="LeftHandIndex2_link_0" />
    <limit effort="1000.0" lower="0" upper="1.334" velocity="1" />
    <origin rpy="-1.570796 3.141592 -0.000000" xyz="-0.033000 0.000000 0.000000" />
    <axis xyz="-0.000000 0.000000 -1.000000" />
  </joint>
  <joint name="LeftHandIndex1_joint_1" type="revolute">
    <parent link="LeftHandIndex1_link_0" />
    <child link="LeftHandIndex1_link_1" />
    <limit effort="1000.0" upper="0.436" lower="-0.61" velocity="1" />
    <origin rpy="1.570700 -3.141592 -0.000000" xyz="-0.000000 0.000000 0.000000" />
    <axis xyz="-0.000000 0.000000 -1.000000" />
  </joint>
  
  <joint name="LeftHandIndex3_joint_0" type="revolute">
    <parent link="LeftHandIndex2_link_0" />
    <child link="LeftHandIndex3_link_0" />
    <limit effort="1000.0" lower="0" upper="1.394" velocity="1" />
    <origin rpy="-0.000000 0.000000 -0.000000" xyz="0.022000 0.000000 0.000000" />
    <axis xyz="-0.000000 0.000000 -1.000000" />
  </joint>
  
  <joint name="LeftHandMiddle1_joint_0" type="revolute">
    <parent link="left_hand_e1" />
    <child link="LeftHandMiddle1_link_0" />
    <limit effort="1000.0" lower="-0.52" upper="1.57" velocity="1" />
    <origin rpy="-0.000000 -1.570700 -0.000000" xyz="-0.003359 0.001478 0.094666" />
    <axis xyz="-0.000000 0.000000 1.000000" />
  </joint>
  <joint name="LeftHandMiddle2_joint_0" type="revolute">
    <parent link="LeftHandMiddle1_link_1" />
    <child link="LeftHandMiddle2_link_0" />
    <limit effort="1000.0" lower="0" upper="1.334" velocity="1" />
    <origin rpy="-1.570796 3.141592 -0.000000" xyz="-0.031735 0.000000 0.000000" />
    <axis xyz="-0.000000 0.000000 -1.000000" />
  </joint>
  <joint name="LeftHandMiddle3_joint_0" type="revolute">
    <parent link="LeftHandMiddle2_link_0" />
    <child link="LeftHandMiddle3_link_0" />
    <limit effort="1000.0" lower="0" upper="1.334" velocity="1" />
    <origin rpy="-0.000000 0.000000 -0.000000" xyz="0.023274 0.000000 0.000000" />
    <axis xyz="-0.000000 0.000000 -1.000000" />
  </joint>
  
  <joint name="LeftHandRing1_joint_1" type="revolute">
    <parent link="LeftHandRing1_link_0" />
    <child link="LeftHandRing1_link_1" />
    <limit effort="1000.0" lower="-0.436" upper="0.174" velocity="1" />
    <origin rpy="1.570700 -3.141592 -0.000000" xyz="-0.000000 0.000000 0.000000" />
    <axis xyz="-0.000000 0.000000 -1.000000" />
  </joint>
  <joint name="LeftHandRing2_joint_0" type="revolute">
    <parent link="LeftHandRing1_link_1" />
    <child link="LeftHandRing2_link_0" />
    <limit effort="1000.0" lower="0" upper="1.334" velocity="1" />
    <origin rpy="-1.570700 3.141592 -0.000000" xyz="-0.028843 0.000000 0.000000" />
    <axis xyz="-0.000000 0.000000 -1.000000" />
  </joint>
  <joint name="LeftHandRing3_joint_0" type="revolute">
    <parent link="LeftHandRing2_link_0" />
    <child link="LeftHandRing3_link_0" />
    <limit effort="1000.0" lower="0" upper="1.395" velocity="1" />
    <origin rpy="-0.000000 0.000000 -0.000000" xyz="0.024786 0.000000 0.000000" />
    <axis xyz="-0.000000 0.000000 -1.000000" />
  </joint>
  
  <joint name="LeftHandPinky1_joint_1" type="revolute">
    <parent link="LeftHandPinky1_link_0" />
    <child link="LeftHandPinky1_link_1" />
    <limit effort="1000.0" lower="-0.7" upper="0.174" velocity="1" />
    <origin rpy="1.570700 -3.141592 -0.000000" xyz="-0.000000 0.000000 0.000000" />
    <axis xyz="-0.000000 0.000000 -1.000000" />
  </joint>
  <joint name="LeftHandPinky2_joint_0" type="revolute">
    <parent link="LeftHandPinky1_link_1" />
    <child link="LeftHandPinky2_link_0" />
    <limit effort="1000.0" lower="0" upper="1.334" velocity="1" />
    <origin rpy="-1.570700 3.141592 -0.000000" xyz="-0.021112 0.000000 0.000000" />
    <axis xyz="-0.000000 0.000000 -1.000000" />
  </joint>
  <joint name="LeftHandPinky3_joint_0" type="revolute">
    <parent link="LeftHandPinky2_link_0" />
    <child link="LeftHandPinky3_link_0" />
    <limit effort="1000.0" lower="0" upper="1.3971" velocity="1" />
    <origin rpy="-0.000000 0.000000 -0.000000" xyz="0.018945 0.000000 0.000000" />
    <axis xyz="-0.000000 0.000000 -1.000000" />
  </joint>
  <joint name="LeftHandIndex1_joint_0" type="revolute">
    <parent link="left_hand_e1" />
    <child link="LeftHandIndex1_link_0" />
    <limit effort="1000.0" upper="1.57" lower="-0.52" velocity="1" />
    <origin rpy="-0.000000 -1.570700 -0.000000" xyz="0.020685 0.005199 0.088103" />
    <axis xyz="-0.000000 0.000000 1.000000" />
  </joint>
  <joint name="LeftHandMiddle1_joint_1" type="revolute">
    <parent link="LeftHandMiddle1_link_0" />
    <child link="LeftHandMiddle1_link_1" />
    <limit effort="1000.0" upper="0.436" lower="-0.61" velocity="1" />
    <origin rpy="1.570700 -3.141592 -0.000000" xyz="-0.000000 0.000000 0.000000" />
    <axis xyz="-0.000000 0.000000 -1.000000" />
  </joint>
  <joint name="LeftHandRing1_joint_0" type="revolute">
    <parent link="left_hand_e2" />
    <child link="LeftHandRing1_link_0" />
    <limit effort="1000.0" lower="-0.52" upper="1.57" velocity="1" />
    <origin rpy="1.570700 -1.570700 -1.570700" xyz="-0.002274 0.003956 0.049681" />
    <axis xyz="-0.000000 0.000000 1.000000" />
  </joint>
  <joint name="LeftHandPinky1_joint_0" type="revolute">
    <parent link="left_hand_e2" />
    <child link="LeftHandPinky1_link_0" />
    <limit effort="1000.0" lower="-0.52" upper="1.57" velocity="1" />
    <origin rpy="1.570700 -1.570700 -1.570700" xyz="-0.018810 0.009939 0.036732" />
    <axis xyz="-0.000000 0.000000 1.000000" />
  </joint>

  <link name="thtip" />
  <link name="fftip" />
  <link name="mftip" />
  <link name="rftip" />
  <link name="lftip" />
  <joint name="thtip_joint" type="fixed">
    <parent link="LeftHandThumb3_link_0" />
    <child link="thtip" />
    <origin rpy="-0.000000 -0.000000 -0.000000" xyz="0.036350 -0.000085 -0.000065" />
  </joint>
  <joint name="fftip_joint" type="fixed">
    <parent link="LeftHandIndex3_link_0" />
    <child link="fftip" />
    <origin rpy="-0.000000 -0.000000 -0.000000" xyz="0.026000 0.000000 0.000000" />
    <axis xyz="-0.000000 0.000000 -1.000000" />
  </joint>
  <joint name="mftip_joint" type="fixed">
    <parent link="LeftHandMiddle3_link_0" />
    <child link="mftip" />
    <origin rpy="-0.000000 -0.000000 -0.000000" xyz="0.026116 0.000000 0.000000" />
    <axis xyz="-0.000000 0.000000 -1.000000" />
  </joint>
  <joint name="rftip_joint" type="fixed">
    <parent link="LeftHandRing3_link_0" />
    <child link="rftip" />
    <origin rpy="-0.000000 -0.000000 -0.000000" xyz="0.025406 0.000000 0.000000" />
    <axis xyz="-0.000000 0.000000 -1.000000" />
  </joint>
  <joint name="lftip_joint" type="fixed">
    <parent link="LeftHandPinky3_link_0" />
    <child link="lftip" />
    <origin rpy="-0.000000 -0.000000 -0.000000" xyz="0.020580 0.000000 0.000000" />
    <axis xyz="-0.000000 0.000000 -1.000000" />
  </joint>
</robot>