<?xml version='1.0' encoding='utf-8'?>
<robot name="gr1t2">
  <link name="base_link">
    <inertial>
      <origin xyz="-0.06032 -9.9E-5 -0.008574" rpy="0 0 0" />
      <mass value="3.96" />
      <inertia ixx="0.04109" ixy="-6E-6" ixz="-0.001996" iyy="0.01336" iyz="-9E-6" izz="0.04269" />
    </inertial>
    <visual>
      <origin xyz="0 0 0" rpy="0 0 0" />
      <geometry>
        <mesh filename="../meshes/gr1t2/base_link.STL" />
      </geometry>
      <material name="">
        <color rgba="0.752941176470588 0.752941176470588 0.752941176470588 1" />
      </material>
    </visual>
    <collision name="base_link.STL">
      <origin xyz="-0.0425828586396115 0.0003700415157537537 0.009210089875386126" rpy="-1.5715560967510487 0.006752722386712318 -0.006757854813246755" />
      <geometry>
        <cylinder radius="0.12239433188500067" length="0.1371007021179978" />
      </geometry>
    </collision>
  </link>
  <link name="left_thigh_roll_link">
    <inertial>
      <origin xyz="0.001095 2.4e-5 0.001761" rpy="0 0 0" />
      <mass value="1.47" />
      <inertia ixx="0.001575" ixy="4e-6" ixz="-6e-6" iyy="0.002478" iyz="-9e-6" izz="0.002575" />
    </inertial>
    <visual>
      <origin xyz="0 0 0" rpy="0 0 0" />
      <geometry>
        <mesh filename="../meshes/gr1t2/left_thigh_roll_link.STL" />
      </geometry>
      <material name="">
        <color rgba="0.752941176470588 0.752941176470588 0.752941176470588 1" />
      </material>
    </visual>
    
  </link>
  <joint name="left_hip_roll_joint" type="revolute">
    <origin xyz="-0.031635 0.105 -0.0276" rpy="0 0 0" />
    <parent link="base_link" />
    <child link="left_thigh_roll_link" />
    <axis xyz="1 0 0" />
    <limit lower="-0.09" upper="0.79" effort="84.18" velocity="7.64" />
  </joint>
  <link name="left_thigh_yaw_link">
    <inertial>
      <origin xyz="-0.000705 0.0384 -0.1103" rpy="0 0 0" />
      <mass value="3.47" />
      <inertia ixx="0.02003" ixy="-0.00165" ixz="0.000145" iyy="0.02123" iyz="0.005516" izz="0.01146" />
    </inertial>
    <visual>
      <origin xyz="0 0 0" rpy="0 0 0" />
      <geometry>
        <mesh filename="../meshes/gr1t2/left_thigh_yaw_link.STL" />
      </geometry>
      <material name="">
        <color rgba="0.752941176470588 0.752941176470588 0.752941176470588 1" />
      </material>
    </visual>
    
  </link>
  <joint name="left_hip_yaw_joint" type="revolute">
    <origin xyz="0.033135 0 0.00075" rpy="0 0 0" />
    <parent link="left_thigh_roll_link" />
    <child link="left_thigh_yaw_link" />
    <axis xyz="0 0 1" />
    <limit lower="-0.7" upper="0.7" effort="65" velocity="9.80" />
  </joint>
  <link name="left_thigh_pitch_link">
    <inertial>
      <origin xyz="0.001387 -0.02832 -0.0640" rpy="0 0 0" />
      <mass value="8.35" />
      <inertia ixx="0.09287" ixy="0.000089" ixz="0.001262" iyy="0.08956" iyz="-0.001832" izz="0.02835" />
    </inertial>
    <visual>
      <origin xyz="0 0 0" rpy="0 0 0" />
      <geometry>
        <mesh filename="../meshes/gr1t2/left_thigh_pitch_link.STL" />
      </geometry>
      <material name="">
        <color rgba="0.752941176470588 0.752941176470588 0.752941176470588 1" />
      </material>
    </visual>
    <collision name="left_thigh_pitch_link.STL">
      <origin xyz="0.0007000513673618543 -0.030 -0.1670560397414535" rpy="0 0 0 " />
      <geometry>
        <cylinder radius="0.082" length="0.24982894507630515" />
      </geometry>
    </collision>
  </link>
  <joint name="left_hip_pitch_joint" type="revolute">
    <origin xyz="0 0.0223 -0.14027" rpy="0 0 0" />
    <parent link="left_thigh_yaw_link" />
    <child link="left_thigh_pitch_link" />
    <axis xyz="0 1 0" />
    <limit lower="-1.75" upper="0.7" effort="135" velocity="18.54" />
  </joint>
  <link name="left_shank_pitch_link">
    <inertial>
      <origin xyz="0.001482 -0.00080 -0.1154" rpy="0 0 0" />
      <mass value="1.76" />
      <inertia ixx="0.01079" ixy="-7e-6" ixz="-0.000149" iyy="0.01068" iyz="-0.000146" izz="0.001262" />
    </inertial>
    <visual>
      <origin xyz="0 0 0" rpy="0 0 0" />
      <geometry>
        <mesh filename="../meshes/gr1t2/left_shank_pitch_link.STL" />
      </geometry>
      <material name="">
        <color rgba="0.752941176470588 0.752941176470588 0.752941176470588 1" />
      </material>
    </visual>
    <collision name="left_shank_pitch_link.STL">
      <origin xyz="-1.659010853856773e-05 -0.000842546786771745 -0.17469107292397335" rpy="-3.1410836913690487 0.0024586308191354433 -2.733338485212507" />
      <geometry>
        <cylinder radius="0.05332138187428352" length="0.18076995129198576" />
      </geometry>
    </collision>
  </link>
  <joint name="left_knee_pitch_joint" type="revolute">
    <origin xyz="0 -0.019512 -0.36" rpy="0 0 0" />
    <parent link="left_thigh_pitch_link" />
    <child link="left_shank_pitch_link" />
    <axis xyz="0 1 0" />
    <limit lower="-0.09" upper="1.92" effort="135" velocity="18.53" />
  </joint>
  <link name="left_foot_pitch_link">
    <inertial>
      <origin xyz="0 0 0" rpy="0 0 0" />
      <mass value="0.057" />
      <inertia ixx="5.31E-6" ixy="0" ixz="0" iyy="5.65E-6" iyz="0" izz="6.36E-6" />
    </inertial>
    <visual>
      <origin xyz="0 0 0" rpy="0 0 0" />
      <geometry>
        <mesh filename="../meshes/gr1t2/left_foot_pitch_link.STL" />
      </geometry>
      <material name="">
        <color rgba="0.752941176470588 0.752941176470588 0.752941176470588 1" />
      </material>
    </visual>
    
  </link>
  <joint name="left_ankle_pitch_joint" type="revolute">
    <origin xyz="0 -0.00125 -0.34" rpy="0 0 0" />
    <parent link="left_shank_pitch_link" />
    <child link="left_foot_pitch_link" />
    <axis xyz="0 1 0" />
    <limit lower="-1.05" upper="0.52" effort="41.67" velocity="10.26" />
  </joint>
  <link name="left_foot_roll_link">
    <inertial>
      <origin xyz="0.0367 0.0001 -0.03837" rpy="0 0 0" />
      <mass value="1.07" />
      <inertia ixx="0.0007664" ixy="3.75E-6" ixz="0.0002441" iyy="0.005085" iyz="-1.53E-6" izz="0.005559" />
    </inertial>
    <visual>
      <origin xyz="0 0 0" rpy="0 0 0" />
      <geometry>
        <mesh filename="../meshes/gr1t2/left_foot_roll_link.STL" />
      </geometry>
      <material name="">
        <color rgba="0.752941176470588 0.752941176470588 0.752941176470588 1" />
      </material>
    </visual>
    

    <collision name="l_foot_1">
      <origin rpy="0 1.5708 0" xyz="0.05 0.02 -0.035" />
      <geometry>
        <cylinder length="0.24" radius="0.02" />
      </geometry>
    </collision>
    <collision name="l_foot_2">
      <origin rpy="0 1.5708 0" xyz="0.05 -0.02 -0.035" />
      <geometry>
        <cylinder length="0.24" radius="0.02" />
      </geometry>
    </collision>
  </link>
  <joint name="left_ankle_roll_joint" type="revolute">
    <origin xyz="0 0 0" rpy="0 0 0" />
    <parent link="left_foot_pitch_link" />
    <child link="left_foot_roll_link" />
    <axis xyz="1 0 0" />
    <limit lower="-0.44" upper="0.44" effort="41.67" velocity="10.26" />
  </joint>
  <link name="right_thigh_roll_link">
    <inertial>
      <origin xyz="0.001319 -9.8e-5 0.001752" rpy="0 0 0" />
      <mass value="1.47" />
      <inertia ixx="0.001572" ixy="1.2e-5" ixz="-5e-6" iyy="0.002502" iyz="6e-6" izz="0.002594" />
    </inertial>
    <visual>
      <origin xyz="0 0 0" rpy="0 0 0" />
      <geometry>
        <mesh filename="../meshes/gr1t2/right_thigh_roll_link.STL" />
      </geometry>
      <material name="">
        <color rgba="0.752941176470588 0.752941176470588 0.752941176470588 1" />
      </material>
    </visual>
    
  </link>
  <joint name="right_hip_roll_joint" type="revolute">
    <origin xyz="-0.031635 -0.105 -0.0276" rpy="0 0 0" />
    <parent link="base_link" />
    <child link="right_thigh_roll_link" />
    <axis xyz="1 0 0" />
    <limit lower="-0.79" upper="0.09" effort="84.18" velocity="7.64" />
  </joint>
  <link name="right_thigh_yaw_link">
    <inertial>
      <origin xyz="-0.000705 -0.03841 -0.1104" rpy="0 0 0" />
      <mass value="3.47" />
      <inertia ixx="0.01912" ixy="-5.8e-5" ixz="0.0000146" iyy="0.02124" iyz="-0.005568" izz="0.01149" />
    </inertial>
    <visual>
      <origin xyz="0 0 0" rpy="0 0 0" />
      <geometry>
        <mesh filename="../meshes/gr1t2/right_thigh_yaw_link.STL" />
      </geometry>
      <material name="">
        <color rgba="0.752941176470588 0.752941176470588 0.752941176470588 1" />
      </material>
    </visual>
    
  </link>
  <joint name="right_hip_yaw_joint" type="revolute">
    <origin xyz="0.033135 0 0.00075" rpy="0 0 0" />
    <parent link="right_thigh_roll_link" />
    <child link="right_thigh_yaw_link" />
    <axis xyz="0 0 1" />
    <limit lower="-0.7" upper="0.7" effort="65" velocity="9.80" />
  </joint>
  <link name="right_thigh_pitch_link">
    <inertial>
      <origin xyz="0.001386 0.02815 -0.06399" rpy="0 0 0" />
      <mass value="8.35" />
      <inertia ixx="0.09315" ixy="9e-5" ixz="0.001548" iyy="0.08956" iyz="-0.001825" izz="0.028" />
    </inertial>
    <visual>
      <origin xyz="0 0 0" rpy="0 0 0" />
      <geometry>
        <mesh filename="../meshes/gr1t2/right_thigh_pitch_link.STL" />
      </geometry>
      <material name="">
        <color rgba="0.752941176470588 0.752941176470588 0.752941176470588 1" />
      </material>
    </visual>
    <collision name="right_thigh_pitch_link.STL">
      <origin xyz="-0.0021232671369708286 0.030 -0.16705638592" rpy="0.005397062281218166 0.014125499755146664 3.8118827309907216e-05" />
      <geometry>
        <cylinder radius="0.082" length="0.24982123520352716" />
      </geometry>
    </collision>
  </link>
  <joint name="right_hip_pitch_joint" type="revolute">
    <origin xyz="0 -0.0223 -0.14027" rpy="0 0 0" />
    <parent link="right_thigh_yaw_link" />
    <child link="right_thigh_pitch_link" />
    <axis xyz="0 1 0" />
    <limit lower="-1.75" upper="0.7" effort="135" velocity="18.54" />
  </joint>
  <link name="right_shank_pitch_link">
    <inertial>
      <origin xyz="0.001486 0.000785 -0.1152" rpy="0 0 0" />
      <mass value="1.76" />
      <inertia ixx="0.01075" ixy="7e-6" ixz="-8.7e-5" iyy="0.01063" iyz="0.00014" izz="0.001242" />
    </inertial>
    <visual>
      <origin xyz="0 0 0" rpy="0 0 0" />
      <geometry>
        <mesh filename="../meshes/gr1t2/right_shank_pitch_link.STL" />
      </geometry>
      <material name="">
        <color rgba="0.752941176470588 0.752941176470588 0.752941176470588 1" />
      </material>
    </visual>
    <collision name="right_shank_pitch_link.STL">
      <origin xyz="-1.6590107921902e-5 -0.000842557381796573 -0.17469872467626" rpy="0 0 0" />
      <geometry>
        <cylinder radius="0.053321055277056" length="0.180768239886" />
      </geometry>
    </collision>
  </link>
  <joint name="right_knee_pitch_joint" type="revolute">
    <origin xyz="0 0.019762 -0.36" rpy="0 0 0" />
    <parent link="right_thigh_pitch_link" />
    <child link="right_shank_pitch_link" />
    <axis xyz="0 1 0" />
    <limit lower="-0.09" upper="1.92" effort="135" velocity="18.54" />
  </joint>
  <link name="right_foot_pitch_link">
    <inertial>
      <origin xyz="0 0 0" rpy="0 0 0" />
      <mass value="0.057" />
      <inertia ixx="5.31E-6" ixy="0" ixz="0" iyy="5.56E-6" iyz="0" izz="6.36E-6" />
    </inertial>
    <visual>
      <origin xyz="0 0 0" rpy="0 0 0" />
      <geometry>
        <mesh filename="../meshes/gr1t2/right_foot_pitch_link.STL" />
      </geometry>
      <material name="">
        <color rgba="0.752941176470588 0.752941176470588 0.752941176470588 1" />
      </material>
    </visual>
    
  </link>
  <joint name="right_ankle_pitch_joint" type="revolute">
    <origin xyz="0 0.00125 -0.34" rpy="0 0 0" />
    <parent link="right_shank_pitch_link" />
    <child link="right_foot_pitch_link" />
    <axis xyz="0 1 0" />
    <limit lower="-1.05" upper="0.52" effort="41.67" velocity="10.26" />
  </joint>
  <link name="right_foot_roll_link">
    <inertial>
      <origin xyz="0.0367 -0.0001 -0.03837" rpy="0 0 0" />
      <mass value="1.07" />
      <inertia ixx="0.0007664" ixy="-3.75E-6" ixz="0.0002441" iyy="0.005085" iyz="1.53E-6" izz="0.005559" />
    </inertial>
    <visual>
      <origin xyz="0 0 0" rpy="0 0 0" />
      <geometry>
        <mesh filename="../meshes/gr1t2/right_foot_roll_link.STL" />
      </geometry>
      <material name="">
        <color rgba="0.752941176470588 0.752941176470588 0.752941176470588 1" />
      </material>
    </visual>
    

    <collision name="r_foot_1">
      <origin rpy="0 1.5708 0" xyz="0.05 0.02 -0.035" />
      <geometry>
        <cylinder length="0.24" radius="0.02" />
      </geometry>
    </collision>
    <collision name="r_foot_2">
      <origin rpy="0 1.5708 0" xyz="0.05 -0.02 -0.035" />
      <geometry>
        <cylinder length="0.24" radius="0.02" />
      </geometry>
    </collision>
  </link>
  <joint name="right_ankle_roll_joint" type="revolute">
    <origin xyz="0 0 0" rpy="0 0 0" />
    <parent link="right_foot_pitch_link" />
    <child link="right_foot_roll_link" />
    <axis xyz="1 0 0" />
    <limit lower="-0.44" upper="0.44" effort="41.67" velocity="10.26" />
  </joint>
  <link name="waist_yaw_link">
    <inertial>
      <origin xyz="-0.00152 -0.00691 0.05223" rpy="0 0 0" />
      <mass value="1.66" />
      <inertia ixx="0.003573" ixy="1.476E-05" ixz="5.805E-05" iyy="0.0031429" iyz="0.00039781" izz="0.0023119" />
    </inertial>
    <visual>
      <origin xyz="0 0 0" rpy="0 0 0" />
      <geometry>
        <mesh filename="../meshes/gr1t2/waist_yaw_link.STL" />
      </geometry>
      <material name="">
        <color rgba="0.752941176470588 0.752941176470588 0.752941176470588 1" />
      </material>
    </visual>
    
  </link>
  <joint name="waist_yaw_joint" type="revolute">
    <origin xyz="0 0 0" rpy="0 0 0" />
    <parent link="base_link" />
    <child link="waist_yaw_link" />
    <axis xyz="0 0 1" />
    <limit lower="-1.05" upper="1.05" effort="65" velocity="9.80" />
  </joint>
  <link name="waist_pitch_link">
    <inertial>
      <origin xyz="0.004581 -0.004697 0.04034" rpy="0 0 0" />
      <mass value="1.54" />
      <inertia ixx="0.0046064" ixy="-2.297E-05" ixz="-0.00026084" iyy="0.0045722" iyz="-0.00024591" izz="0.0018747" />
    </inertial>
    <visual>
      <origin xyz="0 0 0" rpy="0 0 0" />
      <geometry>
        <mesh filename="../meshes/gr1t2/waist_pitch_link.STL" />
      </geometry>
      <material name="">
        <color rgba="0.752941176470588 0.752941176470588 0.752941176470588 1" />
      </material>
    </visual>
    
  </link>
  <joint name="waist_pitch_joint" type="revolute">
    <origin xyz="0 0 0.0869" rpy="0 0 0" />
    <parent link="waist_yaw_link" />
    <child link="waist_pitch_link" />
    <axis xyz="0 1 0" />
    <limit lower="-0.52" upper="1.22" effort="65" velocity="9.80" />
  </joint>
  <link name="waist_roll_link">
    <inertial>
      <origin xyz="0.00823 0.00004 0.01227" rpy="0 0 0" />
      <mass value="0.96" />
      <inertia ixx="0.00100959" ixy="4.9E-7" ixz="9.99E-5" iyy="1.30981E-3" iyz="-5.3E-7" izz="1.16922E-3" />
    </inertial>
    <visual>
      <origin xyz="0 0 0" rpy="0 0 0" />
      <geometry>
        <mesh filename="../meshes/gr1t2/waist_roll_link.STL" />
      </geometry>
      <material name="">
        <color rgba="0.752941176470588 0.752941176470588 0.752941176470588 1" />
      </material>
    </visual>
    
  </link>
  <joint name="waist_roll_joint" type="revolute">
    <origin xyz="0.00525 -0.0005 0.081" rpy="0 0 0" />
    <parent link="waist_pitch_link" />
    <child link="waist_roll_link" />
    <axis xyz="1 0 0" />
    <limit lower="-0.7" upper="0.7" effort="65" velocity="9.80" />
  </joint>
  <link name="torso_link">
    <inertial>
      <origin xyz="-0.01325 0.000292 0.009517" rpy="0 0 0" />
      <mass value="5.67" />
      <inertia ixx="0.04082" ixy="-2e-6" ixz="-0.00047" iyy="0.03729" iyz="-1.4e-5" izz="0.03397" />
    </inertial>
    <visual>
      <origin xyz="0 0 0" rpy="0 0 0" />
      <geometry>
        <mesh filename="../meshes/gr1t2/torso_link.STL" />
      </geometry>
      <material name="">
        <color rgba="0.752941176470588 0.752941176470588 0.752941176470588 1" />
      </material>
    </visual>
    <collision name="torso_link.STL">
      <origin xyz="-0.0158159258618006 0.005195369607133852 -0.01252051000214107" rpy="0 0 0" />
      <geometry>
        <cylinder radius="0.15742740516179015" length="0.0603859984881334" />
      </geometry>
    </collision>
  </link>
  <joint name="torso_joint" type="fixed">
    <origin xyz="-0.00225 0.00057443 0.16035" rpy="0 0 0" />
    <parent link="waist_roll_link" />
    <child link="torso_link" />
    <axis xyz="0 0 0" />
  </joint>
  <link name="left_upper_arm_pitch_link">
    <inertial>
      <origin xyz="0.0033 0.05361 -0.00011" rpy="0 0 0" />
      <mass value="0.82" />
      <inertia ixx="2.04209E-3" ixy="-1.0845E-4" ixz="-5.7E-6" iyy="5.02E-4" iyz="-2.88E-6" izz="1.98176E-3" />
    </inertial>
    <visual>
      <origin xyz="0 0 0" rpy="0 0 0" />
      <geometry>
        <mesh filename="../meshes/gr1t2/left_upper_arm_pitch_link.STL" />
      </geometry>
      <material name="">
        <color rgba="0.752941176470588 0.752941176470588 0.752941176470588 1" />
      </material>
    </visual>
    
  </link>
  <joint name="left_shoulder_pitch_joint" type="revolute">
    <origin xyz="0 0.10128 0.046651" rpy="0.43275 0 0" />
    <parent link="torso_link" />
    <child link="left_upper_arm_pitch_link" />
    <axis xyz="0 1 0" />
    <limit lower="-2.79" upper="1.92" effort="38.46" velocity="6.28" />
  </joint>
  <link name="left_upper_arm_roll_link">
    <inertial>
      <origin xyz="0.005026 0.01740 -0.02398" rpy="0 0 0" />
      <mass value="0.61" />
      <inertia ixx="0.0010175" ixy="8.5E-07" ixz="-2.686E-05" iyy="0.00080346" iyz="0.00031013" izz="0.00056524" />
    </inertial>
    <visual>
      <origin xyz="0 0 0" rpy="0 0 0" />
      <geometry>
        <mesh filename="../meshes/gr1t2/left_upper_arm_roll_link.STL" />
      </geometry>
      <material name="">
        <color rgba="0.752941176470588 0.752941176470588 0.752941176470588 1" />
      </material>
    </visual>
    
  </link>
  <joint name="left_shoulder_roll_joint" type="revolute">
    <origin xyz="0 0.09515 0" rpy="-0.43275 0 0" />
    <parent link="left_upper_arm_pitch_link" />
    <child link="left_upper_arm_roll_link" />
    <axis xyz="1 0 0" />
    <limit lower="-0.57" upper="2.53" effort="38.46" velocity="6.28" />
  </joint>
  <link name="left_upper_arm_yaw_link">
    <inertial>
      <origin xyz="-1.7E-5 -0.0002 -0.08761" rpy="0 0 0" />
      <mass value="0.54" />
      <inertia ixx="0.0035571" ixy="-1.6E-07" ixz="-7.1E-07" iyy="0.003544" iyz="4.560E-05" izz="0.00026034" />
    </inertial>
    <visual>
      <origin xyz="0 0 0" rpy="0 0 0" />
      <geometry>
        <mesh filename="../meshes/gr1t2/left_upper_arm_yaw_link.STL" />
      </geometry>
      <material name="">
        <color rgba="0.752941176470588 0.752941176470588 0.752941176470588 1" />
      </material>
    </visual>
    <collision name="left_upper_arm_yaw_link.STL">
      <origin xyz="3.948544275722503e-05 -0.0008942898235348745 -0.079340036492981" rpy="-3.1255954464984725 0.0015124792767218231 -0.1885285227575202" />
      <geometry>
        <cylinder radius="0.03623321337242011" length="0.1698839909625244" />
      </geometry>
    </collision>
  </link>
  <joint name="left_shoulder_yaw_joint" type="revolute">
    <origin xyz="0 0.04 -0.0709" rpy="0 0 0" />
    <parent link="left_upper_arm_roll_link" />
    <child link="left_upper_arm_yaw_link" />
    <axis xyz="0 0 1" />
    <limit lower="-2.97" upper="2.97" effort="30.3" velocity="5.24" />
  </joint>
  <link name="left_lower_arm_pitch_link">
    <inertial>
      <origin xyz="0 0.008102 -0.02528" rpy="0 0 0" />
      <mass value="0.33" />
      <inertia ixx="0.00029558" ixy="2E-08" ixz="7E-08" iyy="0.000287" iyz="-5.014E-05" izz="0.00011171" />
    </inertial>
    <visual>
      <origin xyz="0 0 0" rpy="0 0 0" />
      <geometry>
        <mesh filename="../meshes/gr1t2/left_lower_arm_pitch_link.STL" />
      </geometry>
      <material name="">
        <color rgba="0.752941176470588 0.752941176470588 0.752941176470588 1" />
      </material>
    </visual>
    
  </link>
  <joint name="left_elbow_pitch_joint" type="revolute">
    <origin xyz="0 0.0010503 -0.1786" rpy="0 0 0" />
    <parent link="left_upper_arm_yaw_link" />
    <child link="left_lower_arm_pitch_link" />
    <axis xyz="0 1 0" />
    <limit lower="-2.27" upper="2.27" effort="30.3" velocity="5.24" />
  </joint>
  <link name="left_hand_yaw_link">
    <inertial>
      <origin xyz="0.00044 0.00196 -0.07313" rpy="0 0 0" />
      <mass value="0.99" />
      <inertia ixx="0.0026215" ixy="1.29E-06" ixz="6.12E-06" iyy="0.0025491" iyz="-1.585E-05" izz="0.00049784" />
    </inertial>
    <visual>
      <origin xyz="0 0 0" rpy="0 0 0" />
      <geometry>
        <mesh filename="../meshes/gr1t2/left_hand_yaw_link.STL" />
      </geometry>
      <material name="">
        <color rgba="0.752941176470588 0.752941176470588 0.752941176470588 1" />
      </material>
    </visual>
    <collision name="left_hand_yaw_link.STL">
      <origin xyz="0.0010892501812804515 -0.0015411136604867 -0.07604285011805535" rpy="0 0 0" />
      <geometry>
        <cylinder radius="0.04157192402358859" length="0.1391873595177893" />
      </geometry>
    </collision>
  </link>
  <joint name="left_wrist_yaw_joint" type="revolute">
    <origin xyz="0 0 -0.05945" rpy="0 0 0" />
    <parent link="left_lower_arm_pitch_link" />
    <child link="left_hand_yaw_link" />
    <axis xyz="0 0 1" />
    <limit lower="-2.97" upper="2.97" effort="13.17" velocity="16.55" />
  </joint>
  <link name="left_hand_roll_link">
    <inertial>
      <origin xyz="0 0 0" rpy="0 0 0" />
      <mass value="0.005" />
      <inertia ixx="7E-8" ixy="0" ixz="0" iyy="3.5E-7" iyz="0" izz="3.5E-7" />
    </inertial>
    <visual>
      <origin xyz="0 0 0" rpy="0 0 0" />
      <geometry>
        <mesh filename="../meshes/gr1t2/left_hand_roll_link.STL" />
      </geometry>
      <material name="">
        <color rgba="0.752941176470588 0.752941176470588 0.752941176470588 1" />
      </material>
    </visual>
    
  </link>
  <joint name="left_wrist_roll_joint" type="revolute">
    <origin xyz="0 0 -0.19115" rpy="0 0 0" />
    <parent link="left_hand_yaw_link" />
    <child link="left_hand_roll_link" />
    <axis xyz="1 0 0" />
    <limit lower="-0.87" upper="0.96" effort="5.25" velocity="15.08" />
  </joint>
  <link name="left_hand_pitch_link">
    <inertial>
      <origin xyz="0 0.00567 -0.00938" rpy="0 0 0" />
      <mass value="0.05" />
      <inertia ixx="1.065E-5" ixy="0" ixz="0" iyy="1.947E-5" iyz="-1.1E-6" izz="2.011E-5" />
    </inertial>
    <visual>
      <origin xyz="0 0 0" rpy="0 0 0" />
      <geometry>
        <mesh filename="../meshes/gr1t2/left_hand_pitch_link.STL" />
      </geometry>
      <material name="">
        <color rgba="0.752941176470588 0.752941176470588 0.752941176470588 1" />
      </material>
    </visual>
    
  </link>
  <joint name="left_wrist_pitch_joint" type="revolute">
    <origin xyz="0 0 0" rpy="0 0 0" />
    <parent link="left_hand_roll_link" />
    <child link="left_hand_pitch_link" />
    <axis xyz="0 1 0" />
    <limit lower="-0.61" upper="0.61" effort="5.25" velocity="15.08" />
  </joint>



  <link name="left_end_effector_link">
  </link>
  <joint name="left_end_effector_joint" type="fixed">
    <origin xyz="0 0 -0.023" rpy="0 0 0" />
    <parent link="left_hand_pitch_link" />
    <child link="left_end_effector_link" />
  </joint>


  <link name="right_upper_arm_pitch_link">
    <inertial>
      <origin xyz="0.00338 -0.05364 0.00021" rpy="0 0 0" />
      <mass value="0.82" />
      <inertia ixx="0.0020452" ixy="0.00011066" ixz="-3.5E-07" iyy="0.00050607" iyz="-3.27E-06" izz="0.0019775" />
    </inertial>
    <visual>
      <origin xyz="0 0 0" rpy="0 0 0" />
      <geometry>
        <mesh filename="../meshes/gr1t2/right_upper_arm_pitch_link.STL" />
      </geometry>
      <material name="">
        <color rgba="0.752941176470588 0.752941176470588 0.752941176470588 1" />
      </material>
    </visual>
    
  </link>
  <joint name="right_shoulder_pitch_joint" type="revolute">
    <origin xyz="0 -0.10128 0.046651" rpy="-0.43275 0 0" />
    <parent link="torso_link" />
    <child link="right_upper_arm_pitch_link" />
    <axis xyz="0 1 0" />
    <limit lower="-2.79" upper="1.92" effort="38.46" velocity="6.28" />
  </joint>
  <link name="right_upper_arm_roll_link">
    <inertial>
      <origin xyz="0.004503 -0.0174 -0.02398" rpy="0 0 0" />
      <mass value="0.61" />
      <inertia ixx="0.0010174" ixy="-8.4E-07" ixz="-2.687E-05" iyy="0.0008033" iyz="-0.00031043" izz="0.00056542" />
    </inertial>
    <visual>
      <origin xyz="0 0 0" rpy="0 0 0" />
      <geometry>
        <mesh filename="../meshes/gr1t2/right_upper_arm_roll_link.STL" />
      </geometry>
      <material name="">
        <color rgba="0.752941176470588 0.752941176470588 0.752941176470588 1" />
      </material>
    </visual>
    
  </link>
  <joint name="right_shoulder_roll_joint" type="revolute">
    <origin xyz="0 -0.09515 0" rpy="0.43275 0 0" />
    <parent link="right_upper_arm_pitch_link" />
    <child link="right_upper_arm_roll_link" />
    <axis xyz="1 0 0" />
    <limit lower="-2.53" upper="0.57" effort="38.46" velocity="6.28" />
  </joint>
  <link name="right_upper_arm_yaw_link">
    <inertial>
      <origin xyz="-1E-5 0.0002 -0.08761" rpy="0 0 0" />
      <mass value="0.54" />
      <inertia ixx="0.0035706" ixy="3E-08" ixz="7E-08" iyy="0.0035441" iyz="-4.555E-05" izz="0.00026029" />
    </inertial>
    <visual>
      <origin xyz="0 0 0" rpy="0 0 0" />
      <geometry>
        <mesh filename="../meshes/gr1t2/right_upper_arm_yaw_link.STL" />
      </geometry>
      <material name="">
        <color rgba="0.752941176470588 0.752941176470588 0.752941176470588 1" />
      </material>
    </visual>
    <collision name="right_upper_arm_yaw_link.STL">
      <origin xyz="3.948544275722503e-05 0.0008942898235348745 -0.079340036492981" rpy="0 0 0" />
      <geometry>
        <cylinder radius="0.03623321337242011" length="0.1698839909625244" />
      </geometry>
    </collision>
  </link>
  <joint name="right_shoulder_yaw_joint" type="revolute">
    <origin xyz="0 -0.04 -0.0709" rpy="0 0 0" />
    <parent link="right_upper_arm_roll_link" />
    <child link="right_upper_arm_yaw_link" />
    <axis xyz="0 0 1" />
    <limit lower="-2.97" upper="2.97" effort="30.3" velocity="5.24" />
  </joint>
  <link name="right_lower_arm_pitch_link">
    <inertial>
      <origin xyz="0 -0.008102 -0.02528" rpy="0 0 0" />
      <mass value="0.33" />
      <inertia ixx="0.00029558" ixy="2E-08" ixz="-7E-08" iyy="0.000287" iyz="5.014E-05" izz="0.000112" />
    </inertial>
    <visual>
      <origin xyz="0 0 0" rpy="0 0 0" />
      <geometry>
        <mesh filename="../meshes/gr1t2/right_lower_arm_pitch_link.STL" />
      </geometry>
      <material name="">
        <color rgba="0.752941176470588 0.752941176470588 0.752941176470588 1" />
      </material>
    </visual>
    
  </link>
  <joint name="right_elbow_pitch_joint" type="revolute">
    <origin xyz="0 -0.0010503 -0.1786" rpy="0 0 0" />
    <parent link="right_upper_arm_yaw_link" />
    <child link="right_lower_arm_pitch_link" />
    <axis xyz="0 1 0" />
    <limit lower="-2.27" upper="2.27" effort="30.3" velocity="5.24" />
  </joint>
  <link name="right_hand_yaw_link">
    <inertial>
      <origin xyz="0.00047 -0.00196 -0.07239" rpy="0 0 0" />
      <mass value="0.99" />
      <inertia ixx="0.0025979" ixy="3.47E-06" ixz="2.86E-06" iyy="0.0025255" iyz="1.62E-05" izz="0.00049776" />
    </inertial>
    <visual>
      <origin xyz="0 0 0" rpy="0 0 0" />
      <geometry>
        <mesh filename="../meshes/gr1t2/right_hand_yaw_link.STL" />
      </geometry>
      <material name="">
        <color rgba="0.752941176470588 0.752941176470588 0.752941176470588 1" />
      </material>
    </visual>
    <collision name="right_hand_yaw_link.STL">
      <origin xyz="0.0010892501812804515 0.0006411136604867 -0.07604285011805535" rpy="0 0 0" />
      <geometry>
        <cylinder radius="0.04157192402358859" length="0.1391873595177893" />
      </geometry>
    </collision>
  </link>
  <joint name="right_wrist_yaw_joint" type="revolute">
    <origin xyz="0 0 -0.05945" rpy="0 0 0" />
    <parent link="right_lower_arm_pitch_link" />
    <child link="right_hand_yaw_link" />
    <axis xyz="0 0 1" />
    <limit lower="-2.97" upper="2.97" effort="13.17" velocity="16.55" />
  </joint>
  <link name="right_hand_roll_link">
    <inertial>
      <origin xyz="0 0 0" rpy="0 0 0" />
      <mass value="0.005" />
      <inertia ixx="7E-8" ixy="0" ixz="0" iyy="3.5E-7" iyz="0" izz="3.5E-7" />
    </inertial>
    <visual>
      <origin xyz="0 0 0" rpy="0 0 0" />
      <geometry>
        <mesh filename="../meshes/gr1t2/right_hand_roll_link.STL" />
      </geometry>
      <material name="">
        <color rgba="0.752941176470588 0.752941176470588 0.752941176470588 1" />
      </material>
    </visual>
    
  </link>
  <joint name="right_wrist_roll_joint" type="revolute">
    <origin xyz="0 0 -0.19115" rpy="0 0 0" />
    <parent link="right_hand_yaw_link" />
    <child link="right_hand_roll_link" />
    <axis xyz="1 0 0" />
    <limit lower="-0.96" upper="0.87" effort="5.25" velocity="15.08" />
  </joint>
  <link name="right_hand_pitch_link">
    <inertial>
      <origin xyz="0 -0.00567 -0.00938" rpy="0 0 0" />
      <mass value="0.05" />
      <inertia ixx="1.065E-5" ixy="0" ixz="0" iyy="1.96E-5" iyz="1.1E-6" izz="2.022E-5" />
    </inertial>
    <visual>
      <origin xyz="0 0 0" rpy="0 0 0" />
      <geometry>
        <mesh filename="../meshes/gr1t2/right_hand_pitch_link.STL" />
      </geometry>
      <material name="">
        <color rgba="0.752941176470588 0.752941176470588 0.752941176470588 1" />
      </material>
    </visual>
    
  </link>
  <joint name="right_wrist_pitch_joint" type="revolute">
    <origin xyz="0 0 0" rpy="0 0 0" />
    <parent link="right_hand_roll_link" />
    <child link="right_hand_pitch_link" />
    <axis xyz="0 1 0" />
    <limit lower="-0.61" upper="0.61" effort="5.25" velocity="15.08" />
  </joint>


  <link name="right_end_effector_link">
  </link>
  <joint name="right_end_effector_joint" type="fixed">
    <origin xyz="0 0 -0.023" rpy="0 0 0" />
    <parent link="right_hand_pitch_link" />
    <child link="right_end_effector_link" />
  </joint>


  <link name="head_roll_link">
    <inertial>
      <origin xyz="0.00425 0 0" rpy="0 0 0" />
      <mass value="0.01" />
      <inertia ixx="4.3E-7" ixy="0" ixz="0" iyy="4.4E-7" iyz="0" izz="7.2E-7" />
    </inertial>
    <visual>
      <origin xyz="0 0 0" rpy="0 0 0" />
      <geometry>
        <mesh filename="../meshes/gr1t2/head_roll_link.STL" />
      </geometry>
      <material name="">
        <color rgba="0.752941176470588 0.752941176470588 0.752941176470588 1" />
      </material>
    </visual>
    
  </link>
  <joint name="head_roll_joint" type="revolute">
    <origin xyz="0.002 0.0005184 0.14465" rpy="0 0 0" />
    <parent link="torso_link" />
    <child link="head_roll_link" />
    <axis xyz="1 0 0" />
    <limit lower="-0.35" upper="0.35" effort="5.25" velocity="15.08" />
  </joint>
  <link name="head_pitch_link">
    <inertial>
      <origin xyz="-0.0021765 -4.1784E-07 0.017509" rpy="0 0 0" />
      <mass value="0.06" />
      <inertia ixx="2.509E-05" ixy="0" ixz="-1.3E-06" iyy="1.707E-05" iyz="0" izz="2.462E-05" />
    </inertial>
    <visual>
      <origin xyz="0 0 0" rpy="0 0 0" />
      <geometry>
        <mesh filename="../meshes/gr1t2/head_pitch_link.STL" />
      </geometry>
      <material name="">
        <color rgba="0.752941176470588 0.752941176470588 0.752941176470588 1" />
      </material>
    </visual>
    
  </link>
  <joint name="head_pitch_joint" type="revolute">
    <origin xyz="0 0 0" rpy="0 0 0" />
    <parent link="head_roll_link" />
    <child link="head_pitch_link" />
    <axis xyz="0 1 0" />
    <limit lower="-0.87" upper="0.87" effort="5.25" velocity="15.08" />
  </joint>
  <link name="head_yaw_link">
    <inertial>
      <origin xyz="0.02710 -0.00206 0.09577" rpy="0 0 0" />
      <mass value="1.58" />
      <inertia ixx="7.54439E-3" ixy="7.210E-5" ixz="9.5183E-4" iyy="0.01013433" iyz="5.051E-5" izz="5.65975E-3" />
    </inertial>
    <visual>
      <origin xyz="0 0 0" rpy="0 0 0" />
      <geometry>
        <mesh filename="../meshes/gr1t2/head_yaw_link.STL" />
      </geometry>
      <material name="">
        <color rgba="0.752941176470588 0.752941176470588 0.752941176470588 1" />
      </material>
    </visual>
    <collision name="head_yaw_link.STL">
      <origin xyz="0.018281080808229797 -0.0008800241069948287 0.0936201800288447" rpy="0 0 0" />
      <geometry>
        <sphere radius="0.1186868692306477" />
      </geometry>
    </collision>
  </link>
  <joint name="head_yaw_joint" type="revolute">
    <origin xyz="0 0 0.0513" rpy="0 0 0" />
    <parent link="head_pitch_link" />
    <child link="head_yaw_link" />
    <axis xyz="0 0 1" />
    <limit lower="-2.71" upper="2.71" effort="5.25" velocity="15.08" />
  </joint>
  <link name="imu_link">
    <inertial>
      <origin xyz="-0.062133 -1.5129E-06 -0.003126" rpy="0 0 0" />
      <mass value="0.05" />
      <inertia ixx="1.125E-05" ixy="0" ixz="8.8E-07" iyy="1.67E-05" iyz="0" izz="1.983E-05" />
    </inertial>
    <visual>
      <origin xyz="0 0 0" rpy="0 0 0" />
      <geometry>
        <mesh filename="../meshes/gr1t2/imu_link.STL" />
      </geometry>
      <material name="">
        <color rgba="0.752941176470588 0.752941176470588 0.752941176470588 1" />
      </material>
    </visual>
    
  </link>
  <joint name="imu_joint" type="fixed">
    <origin xyz="0 0 -0.0595999999999995" rpy="0 0 0" />
    <parent link="base_link" />
    <child link="imu_link" />
    <axis xyz="0 0 0" />
  </joint>
<link name="L_hand_base_link">
    <inertial>
      <origin xyz="-0.0025784 -0.0012134 -0.054617" rpy="0 0 0" />
      <mass value="0.26434" />
      <inertia ixx="0.0002497" ixy="7.84E-06" ixz="9.3E-07" iyy="0.00034878" iyz="8E-07" izz="0.00018825" />
    </inertial>
    <visual>
      <origin xyz="0 0 0" rpy="0 0 0" />
      <geometry>
        <mesh filename="../meshes/fourier_hand_12dof_v2/L_hand_base_link.STL" />
      </geometry>
      <material name="">
        <color rgba="1 1 1 1" />
      </material>
    </visual>
    <collision>
      <origin xyz="0 0 0" rpy="0 0 0" />
      <geometry>
        <mesh filename="../meshes/fourier_hand_12dof_v2/L_hand_base_link.STL" />
      </geometry>
    </collision>
  </link>
  <link name="L_hand_wrist_link">
  </link>
  <link name="L_thumb_proximal_yaw_link">
    <inertial>
      <origin xyz="0.01106 -0.00242 -0.001058" rpy="0 0 0" />
      <mass value="0.034977" />
      <inertia ixx="2.26E-06" ixy="7.6E-07" ixz="-3.3E-07" iyy="5E-06" iyz="5E-08" izz="4.66E-06" />
    </inertial>
    <visual>
      <origin xyz="0 0 0" rpy="0 0 0" />
      <geometry>
        <mesh filename="../meshes/fourier_hand_12dof_v2/L_thumb_proximal_yaw_link.STL" />
      </geometry>
      <material name="">
        <color rgba="1 1 1 1" />
      </material>
    </visual>
    <collision>
      <origin xyz="0 0 0" rpy="0 0 0" />
      <geometry>
        <mesh filename="../meshes/fourier_hand_12dof_v2/L_thumb_proximal_yaw_link.STL" />
      </geometry>
    </collision>
  </link>
  <link name="L_thumb_proximal_pitch_link">
    <inertial>
      <origin xyz="0.021577 -0.003516 -2.151E-05" rpy="0 0 0" />
      <mass value="0.047552" />
      <inertia ixx="4.41E-06" ixy="-1.9E-07" ixz="-3E-08" iyy="1.192E-05" iyz="0" izz="1.307E-05" />
    </inertial>
    <visual>
      <origin xyz="0 0 0" rpy="0 0 0" />
      <geometry>
        <mesh filename="../meshes/fourier_hand_12dof_v2/L_thumb_proximal_pitch_link.STL" />
      </geometry>
      <material name="">
        <color rgba="1 1 1 1" />
      </material>
    </visual>
    <collision>
      <origin xyz="0 0 0" rpy="0 0 0" />
      <geometry>
        <mesh filename="../meshes/fourier_hand_12dof_v2/L_thumb_proximal_pitch_link.STL" />
      </geometry>
    </collision>
  </link>
  <link name="L_thumb_distal_link">
    <inertial>
      <origin xyz="0.016377 -0.0025204 0" rpy="0 0 0" />
      <mass value="0.021803" />
      <inertia ixx="1.42E-06" ixy="-4.3E-07" ixz="0" iyy="3.85E-06" iyz="0" izz="3.8E-06" />
    </inertial>
    <visual>
      <origin xyz="0 0 0" rpy="0 0 0" />
      <geometry>
        <mesh filename="../meshes/fourier_hand_12dof_v2/L_thumb_distal_link.STL" />
      </geometry>
      <material name="">
        <color rgba="1 1 1 1" />
      </material>
    </visual>
    <collision>
      <origin xyz="0 0 0" rpy="0 0 0" />
      <geometry>
        <mesh filename="../meshes/fourier_hand_12dof_v2/L_thumb_distal_link.STL" />
      </geometry>
    </collision>
  </link>
  <link name="L_thumb_tip_link">
    <visual>
      <origin xyz="0 0 0" rpy="0 0 0" />
      <geometry>
        <sphere radius="0.005" />
      </geometry>
      <material name="yellow">
        <color rgba="0.9 1 0 1" />
      </material>
    </visual>
  </link>
  <link name="L_index_metacarpal_link">
    <inertial>
      <origin xyz="-0.012286 -0.01381 -3.526E-05" rpy="0 0 0" />
      <mass value="0.028947" />
      <inertia ixx="1.91E-06" ixy="-8.7E-07" ixz="-3E-08" iyy="3.56E-06" iyz="-1E-08" izz="4.8E-06" />
    </inertial>
    <visual>
      <origin xyz="0 0 0" rpy="0 0 0" />
      <geometry>
        <mesh filename="../meshes/fourier_hand_12dof_v2/L_index_metacarpal_link.STL" />
      </geometry>
      <material name="">
        <color rgba="1 1 1 1" />
      </material>
    </visual>
    <collision>
      <origin xyz="0 0 0" rpy="0 0 0" />
      <geometry>
        <mesh filename="../meshes/fourier_hand_12dof_v2/L_index_metacarpal_link.STL" />
      </geometry>
    </collision>
  </link>
  <link name="L_index_proximal_link">
    <inertial>
      <origin xyz="0.017015 0.0046443 2.868E-05" rpy="0 0 0" />
      <mass value="0.035619" />
      <inertia ixx="2.19E-06" ixy="-3E-08" ixz="3E-08" iyy="5.3E-06" iyz="0" izz="5.7E-06" />
    </inertial>
    <visual>
      <origin xyz="0 0 0" rpy="0 0 0" />
      <geometry>
        <mesh filename="../meshes/fourier_hand_12dof_v2/L_index_proximal_link.STL" />
      </geometry>
      <material name="">
        <color rgba="1 1 1 1" />
      </material>
    </visual>
    <collision>
      <origin xyz="0 0 0" rpy="0 0 0" />
      <geometry>
        <mesh filename="../meshes/fourier_hand_12dof_v2/L_index_proximal_link.STL" />
      </geometry>
    </collision>
  </link>
  <link name="L_index_intermediate_link">
    <inertial>
      <origin xyz="0.022061 0.00025969 0" rpy="0 0 0" />
      <mass value="0.019358" />
      <inertia ixx="9.3E-07" ixy="3.4E-07" ixz="0" iyy="4.38E-06" iyz="0" izz="4.27E-06" />
    </inertial>
    <visual>
      <origin xyz="0 0 0" rpy="0 0 0" />
      <geometry>
        <mesh filename="../meshes/fourier_hand_12dof_v2/L_index_intermediate_link.STL" />
      </geometry>
      <material name="">
        <color rgba="1 1 1 1" />
      </material>
    </visual>
    <collision>
      <origin xyz="0 0 0" rpy="0 0 0" />
      <geometry>
        <mesh filename="../meshes/fourier_hand_12dof_v2/L_index_intermediate_link.STL" />
      </geometry>
    </collision>
  </link>
  <link name="L_index_tip_link">
    <visual>
      <origin xyz="0 0 0" rpy="0 0 0" />
      <geometry>
        <sphere radius="0.005" />
      </geometry>
      <material name="yellow">
        <color rgba="0.9 1 0 1" />
      </material>
    </visual>
  </link>
  <link name="L_middle_proximal_link">
    <inertial>
      <origin xyz="0.016963 0.004834 2.667E-05" rpy="0 0 0" />
      <mass value="0.035619" />
      <inertia ixx="2.19E-06" ixy="-7E-08" ixz="3E-08" iyy="5.29E-06" iyz="0" izz="5.7E-06" />
    </inertial>
    <visual>
      <origin xyz="0 0 0" rpy="0 0 0" />
      <geometry>
        <mesh filename="../meshes/fourier_hand_12dof_v2/L_middle_proximal_link.STL" />
      </geometry>
      <material name="">
        <color rgba="1 1 1 1" />
      </material>
    </visual>
    <collision>
      <origin xyz="0 0 0" rpy="0 0 0" />
      <geometry>
        <mesh filename="../meshes/fourier_hand_12dof_v2/L_middle_proximal_link.STL" />
      </geometry>
    </collision>
  </link>
  <link name="L_middle_intermediate_link">
    <inertial>
      <origin xyz="0.025092 0.00019 -4.33E-06" rpy="0 0 0" />
      <mass value="0.022377" />
      <inertia ixx="1.09E-06" ixy="5E-07" ixz="0" iyy="6.44E-06" iyz="0" izz="6.32E-06" />
    </inertial>
    <visual>
      <origin xyz="0 0 0" rpy="0 0 0" />
      <geometry>
        <mesh filename="../meshes/fourier_hand_12dof_v2/L_middle_intermediate_link.STL" />
      </geometry>
      <material name="">
        <color rgba="1 1 1 1" />
      </material>
    </visual>
    <collision>
      <origin xyz="0 0 0" rpy="0 0 0" />
      <geometry>
        <mesh filename="../meshes/fourier_hand_12dof_v2/L_middle_intermediate_link.STL" />
      </geometry>
    </collision>
  </link>
  <link name="L_middle_tip_link">
    <visual>
      <origin xyz="0 0 0" rpy="0 0 0" />
      <geometry>
        <sphere radius="0.005" />
      </geometry>
      <material name="yellow">
        <color rgba="0.9 1 0 1" />
      </material>
    </visual>
  </link>
  <link name="L_ring_proximal_link">
    <inertial>
      <origin xyz="0.017015 0.0046443 2.868E-05" rpy="0 0 0" />
      <mass value="0.035619" />
      <inertia ixx="2.19E-06" ixy="-3E-08" ixz="3E-08" iyy="5.3E-06" iyz="0" izz="5.7E-06" />
    </inertial>
    <visual>
      <origin xyz="0 0 0" rpy="0 0 0" />
      <geometry>
        <mesh filename="../meshes/fourier_hand_12dof_v2/L_ring_proximal_link.STL" />
      </geometry>
      <material name="">
        <color rgba="1 1 1 1" />
      </material>
    </visual>
    <collision>
      <origin xyz="0 0 0" rpy="0 0 0" />
      <geometry>
        <mesh filename="../meshes/fourier_hand_12dof_v2/L_ring_proximal_link.STL" />
      </geometry>
    </collision>
  </link>
  <link name="L_ring_intermediate_link">
    <inertial>
      <origin xyz="0.022061 0.00025969 0" rpy="0 0 0" />
      <mass value="0.019358" />
      <inertia ixx="9.3E-07" ixy="3.4E-07" ixz="0" iyy="4.38E-06" iyz="0" izz="4.27E-06" />
    </inertial>
    <visual>
      <origin xyz="0 0 0" rpy="0 0 0" />
      <geometry>
        <mesh filename="../meshes/fourier_hand_12dof_v2/L_ring_intermediate_link.STL" />
      </geometry>
      <material name="">
        <color rgba="1 1 1 1" />
      </material>
    </visual>
    <collision>
      <origin xyz="0 0 0" rpy="0 0 0" />
      <geometry>
        <mesh filename="../meshes/fourier_hand_12dof_v2/L_ring_intermediate_link.STL" />
      </geometry>
    </collision>
  </link>
  <link name="L_ring_tip_link">
    <visual>
      <origin xyz="0 0 0" rpy="0 0 0" />
      <geometry>
        <sphere radius="0.005" />
      </geometry>
      <material name="green">
        <color rgba="0.9 1 0 1" />
      </material>
    </visual>
  </link>
  <link name="L_pinky_proximal_link">
    <inertial>
      <origin xyz="0.017073 0.0044289 2.868E-05" rpy="0 0 0" />
      <mass value="0.035619" />
      <inertia ixx="2.19E-06" ixy="0" ixz="3E-08" iyy="5.3E-06" iyz="-1E-08" izz="5.7E-06" />
    </inertial>
    <visual>
      <origin xyz="0 0 0" rpy="0 0 0" />
      <geometry>
        <mesh filename="../meshes/fourier_hand_12dof_v2/L_pinky_proximal_link.STL" />
      </geometry>
      <material name="">
        <color rgba="1 1 1 1" />
      </material>
    </visual>
    <collision>
      <origin xyz="0 0 0" rpy="0 0 0" />
      <geometry>
        <mesh filename="../meshes/fourier_hand_12dof_v2/L_pinky_proximal_link.STL" />
      </geometry>
    </collision>
  </link>
  <link name="L_pinky_intermediate_link">
    <inertial>
      <origin xyz="0.018249 0.00057564 0" rpy="0 0 0" />
      <mass value="0.01622" />
      <inertia ixx="7.6E-07" ixy="2.1E-07" ixz="0" iyy="2.64E-06" iyz="0" izz="2.57E-06" />
    </inertial>
    <visual>
      <origin xyz="0 0 0" rpy="0 0 0" />
      <geometry>
        <mesh filename="../meshes/fourier_hand_12dof_v2/L_pinky_intermediate_link.STL" />
      </geometry>
      <material name="">
        <color rgba="1 1 1 1" />
      </material>
    </visual>
    <collision>
      <origin xyz="0 0 0" rpy="0 0 0" />
      <geometry>
        <mesh filename="../meshes/fourier_hand_12dof_v2/L_pinky_intermediate_link.STL" />
      </geometry>
    </collision>
  </link>
  <link name="L_pinky_tip_link">
    <visual>
      <origin xyz="0 0 0" rpy="0 0 0" />
      <geometry>
        <sphere radius="0.005" />
      </geometry>
      <material name="yellow">
        <color rgba="0.9 1 0 1" />
      </material>
    </visual>
  </link>
  <joint name="L_hand_wrist_joint" type="fixed">
    <origin xyz="0 0 0" rpy="0 0 0" />
    <parent link="L_hand_base_link" />
    <child link="L_hand_wrist_link" />
    <axis xyz="0 0 0" />
  </joint>


  <joint name="L_thumb_proximal_yaw_joint" type="revolute">
    <origin xyz="0.014 -0.012 -0.022446" rpy="0 0 0" />
    <parent link="L_hand_base_link" />
    <child link="L_thumb_proximal_yaw_link" />
    <axis xyz="0 0 1" />
    <limit lower="-1.3579" upper="0" effort="0" velocity="0" />
  </joint>
  <joint name="L_thumb_proximal_pitch_joint" type="revolute">
    <origin xyz="0.03385 -0.0078588 -0.0005" rpy="-1.5708 0.037538 -0.22813" />
    <parent link="L_thumb_proximal_yaw_link" />
    <child link="L_thumb_proximal_pitch_link" />
    <axis xyz="0 0 1" />
    <limit lower="0" upper="1.206" effort="0" velocity="0" />
  </joint>
  <joint name="L_thumb_distal_joint" type="revolute">
    <origin xyz="0.051711 0.0054792 0" rpy="0 0 -0.12355" />
    <parent link="L_thumb_proximal_pitch_link" />
    <child link="L_thumb_distal_link" />
    <axis xyz="0 0 1" />
    <limit lower="0" upper="1.2078" effort="0" velocity="0" />
  </joint>

  <joint name="L_thumb_tip_joint" type="fixed">
    <parent link="L_thumb_distal_link" />
    <child link="L_thumb_tip_link" />
    <origin rpy="0 0 0" xyz="0.035 0.001 0" />
  </joint>


  <joint name="L_index_metacarpal_joint" type="revolute">
    <origin xyz="0.0305 -0.0113 -0.088496" rpy="0 1.5295 -3.1416" />
    <parent link="L_hand_base_link" />
    <child link="L_index_metacarpal_link" />
    <axis xyz="0 1 0" />
    <limit lower="0" upper="0.295" effort="0" velocity="0" />
  </joint>
  <joint name="L_index_proximal_joint" type="revolute">
    <origin xyz="0.012 0 0" rpy="-3.1416 0 0.041438" />
    <parent link="L_index_metacarpal_link" />
    <child link="L_index_proximal_link" />
    <axis xyz="0 0 1" />
    <limit lower="-1.4172" upper="0" effort="0" velocity="0" />
  </joint>
  <joint name="L_index_intermediate_joint" type="revolute">
    <origin xyz="0.038938 0.0021905 0" rpy="0 0 -0.040106" />
    <parent link="L_index_proximal_link" />
    <child link="L_index_intermediate_link" />
    <axis xyz="0 0 1" />
    <limit lower="-1.4835" upper="0" effort="0" velocity="0" />
  </joint>

  <joint name="L_index_tip_joint" type="fixed">
    <parent link="L_index_intermediate_link" />
    <child link="L_index_tip_link" />
    <origin rpy="0 0 0" xyz="0.047 -0.003 0" />
  </joint>


  <joint name="L_middle_proximal_joint" type="revolute">
    <origin xyz="0.0091 -0.0113 -0.10005" rpy="-1.5685 1.5182 -1.5685" />
    <parent link="L_hand_base_link" />
    <child link="L_middle_proximal_link" />
    <axis xyz="0 0 1" />
    <limit lower="-1.4172" upper="0" effort="0" velocity="0" />
  </joint>
  <joint name="L_middle_intermediate_joint" type="revolute">
    <origin xyz="0.038912 0.0026251 0" rpy="0 -7.4325E-05 -0.04236" />
    <parent link="L_middle_proximal_link" />
    <child link="L_middle_intermediate_link" />
    <axis xyz="0 0 1" />
    <limit lower="-1.4835" upper="0" effort="0" velocity="0" />
  </joint>

  <joint name="L_middle_tip_joint" type="fixed">
    <parent link="L_middle_intermediate_link" />
    <child link="L_middle_tip_link" />
    <origin rpy="0 0 0" xyz="0.055 -0.003 0" />
  </joint>

  <joint name="L_ring_proximal_joint" type="revolute">
    <origin xyz="-0.011187 -0.0113 -0.10003" rpy="-2.4727 1.504 -2.4716" />
    <parent link="L_hand_base_link" />
    <child link="L_ring_proximal_link" />
    <axis xyz="0 0 1" />
    <limit lower="-1.4172" upper="0" effort="0" velocity="0" />
  </joint>
  <joint name="L_ring_intermediate_joint" type="revolute">
    <origin xyz="0.038938 0.0021905 0" rpy="0 0 -0.040106" />
    <parent link="L_ring_proximal_link" />
    <child link="L_ring_intermediate_link" />
    <axis xyz="0 0 1" />
    <limit lower="-1.4835" upper="0" effort="0" velocity="0" />
  </joint>

  <joint name="L_ring_tip_joint" type="fixed">
    <parent link="L_ring_intermediate_link" />
    <child link="L_ring_tip_link" />
    <origin rpy="0 0 0" xyz="0.045 -0.003 0" />
  </joint>


  <joint name="L_pinky_proximal_joint" type="revolute">
    <origin xyz="-0.031472 -0.0113 -0.099245" rpy="-2.8742 1.4622 -2.8727" />
    <parent link="L_hand_base_link" />
    <child link="L_pinky_proximal_link" />
    <axis xyz="0 0 1" />
    <limit lower="-1.4172" upper="0" effort="0" velocity="0" />
  </joint>
  <joint name="L_pinky_intermediate_joint" type="revolute">
    <origin xyz="0.038963 0.0016981 0" rpy="0 0 -0.036802" />
    <parent link="L_pinky_proximal_link" />
    <child link="L_pinky_intermediate_link" />
    <axis xyz="0 0 1" />
    <limit lower="-1.4835" upper="0" effort="0" velocity="0" />
  </joint>

  <joint name="L_pinky_tip_joint" type="fixed">
    <parent link="L_pinky_intermediate_link" />
    <child link="L_pinky_tip_link" />
    <origin rpy="0 0 0" xyz="0.038 -0.003 0" />
  </joint>

<joint name="L_hand_base_joint" type="fixed"><parent link="left_end_effector_link" /><child link="L_hand_base_link" /><origin rpy="0 0 0" xyz="0 0 0" /></joint><link name="R_hand_base_link">
    <inertial>
      <origin xyz="-0.0025758 0.0011993 -0.054629" rpy="0 0 0" />
      <mass value="0.26443" />
      <inertia ixx="0.00024968" ixy="-7.92E-06" ixz="7.5E-07" iyy="0.00034903" iyz="-8.4E-07" izz="0.00018834" />
    </inertial>
    <visual>
      <origin xyz="0 0 0" rpy="0 0 0" />
      <geometry>
        <mesh filename="../meshes/fourier_hand_12dof_v2/R_hand_base_link.STL" />
      </geometry>
      <material name="">
        <color rgba="1 1 1 1" />
      </material>
    </visual>
    <collision>
      <origin xyz="0 0 0" rpy="0 0 0" />
      <geometry>
        <mesh filename="../meshes/fourier_hand_12dof_v2/R_hand_base_link.STL" />
      </geometry>
    </collision>
  </link>

  <link name="R_hand_wrist_link">
  </link>
  <link name="R_thumb_proximal_yaw_link">
    <inertial>
      <origin xyz="0.011297 -0.0024139 0.00088027" rpy="0 0 0" />
      <mass value="0.03498" />
      <inertia ixx="2.28E-06" ixy="8E-07" ixz="3.1E-07" iyy="4.96E-06" iyz="-3E-08" izz="4.62E-06" />
    </inertial>
    <visual>
      <origin xyz="0 0 0" rpy="0 0 0" />
      <geometry>
        <mesh filename="../meshes/fourier_hand_12dof_v2/R_thumb_proximal_yaw_link.STL" />
      </geometry>
      <material name="">
        <color rgba="1 1 1 1" />
      </material>
    </visual>
    <collision>
      <origin xyz="0 0 0" rpy="0 0 0" />
      <geometry>
        <mesh filename="../meshes/fourier_hand_12dof_v2/R_thumb_proximal_yaw_link.STL" />
      </geometry>
    </collision>
  </link>
  <link name="R_thumb_proximal_pitch_link">
    <inertial>
      <origin xyz="0.02157 -0.0035616 -2.386E-05" rpy="0 0 0" />
      <mass value="0.047583" />
      <inertia ixx="4.41E-06" ixy="-1.7E-07" ixz="-3E-08" iyy="1.194E-05" iyz="0" izz="1.308E-05" />
    </inertial>
    <visual>
      <origin xyz="0 0 0" rpy="0 0 0" />
      <geometry>
        <mesh filename="../meshes/fourier_hand_12dof_v2/R_thumb_proximal_pitch_link.STL" />
      </geometry>
      <material name="">
        <color rgba="1 1 1 1" />
      </material>
    </visual>
    <collision>
      <origin xyz="0 0 0" rpy="0 0 0" />
      <geometry>
        <mesh filename="../meshes/fourier_hand_12dof_v2/R_thumb_proximal_pitch_link.STL" />
      </geometry>
    </collision>
  </link>
  <link name="R_thumb_distal_link">
    <inertial>
      <origin xyz="0.016377 -0.0025204 0" rpy="0 0 0" />
      <mass value="0.021803" />
      <inertia ixx="1.42E-06" ixy="-4.3E-07" ixz="0" iyy="3.85E-06" iyz="0" izz="3.8E-06" />
    </inertial>
    <visual>
      <origin xyz="0 0 0" rpy="0 0 0" />
      <geometry>
        <mesh filename="../meshes/fourier_hand_12dof_v2/R_thumb_distal_link.STL" />
      </geometry>
      <material name="">
        <color rgba="1 1 1 1" />
      </material>
    </visual>
    <collision>
      <origin xyz="0 0 0" rpy="0 0 0" />
      <geometry>
        <mesh filename="../meshes/fourier_hand_12dof_v2/R_thumb_distal_link.STL" />
      </geometry>
    </collision>
  </link>
  <link name="R_thumb_tip_link">
    <visual>
      <origin xyz="0 0 0" rpy="0 0 0" />
      <geometry>
        <sphere radius="0.005" />
      </geometry>
      <material name="yellow">
        <color rgba="0.9 1 0 1" />
      </material>
    </visual>
  </link>
  <link name="R_index_metacarpal_link">
    <inertial>
      <origin xyz="-0.012286 0.01381 3.526E-05" rpy="0 0 0" />
      <mass value="0.028947" />
      <inertia ixx="1.91E-06" ixy="8.7E-07" ixz="3E-08" iyy="3.56E-06" iyz="-1E-08" izz="4.8E-06" />
    </inertial>
    <visual>
      <origin xyz="0 0 0" rpy="0 0 0" />
      <geometry>
        <mesh filename="../meshes/fourier_hand_12dof_v2/R_index_metacarpal_link.STL" />
      </geometry>
      <material name="">
        <color rgba="1 1 1 1" />
      </material>
    </visual>
    <collision>
      <origin xyz="0 0 0" rpy="0 0 0" />
      <geometry>
        <mesh filename="../meshes/fourier_hand_12dof_v2/R_index_metacarpal_link.STL" />
      </geometry>
    </collision>
  </link>
  <link name="R_index_proximal_link">
    <inertial>
      <origin xyz="0.017246 0.0047094 2.979E-05" rpy="0 0 0" />
      <mass value="0.035619" />
      <inertia ixx="2.18E-06" ixy="-1E-08" ixz="3E-08" iyy="5.26E-06" iyz="-1E-08" izz="5.69E-06" />
    </inertial>
    <visual>
      <origin xyz="0 0 0" rpy="0 0 0" />
      <geometry>
        <mesh filename="../meshes/fourier_hand_12dof_v2/R_index_proximal_link.STL" />
      </geometry>
      <material name="">
        <color rgba="1 1 1 1" />
      </material>
    </visual>
    <collision>
      <origin xyz="0 0 0" rpy="0 0 0" />
      <geometry>
        <mesh filename="../meshes/fourier_hand_12dof_v2/R_index_proximal_link.STL" />
      </geometry>
    </collision>
  </link>
  <link name="R_index_intermediate_link">
    <inertial>
      <origin xyz="0.022061 0.00025969 0" rpy="0 0 0" />
      <mass value="0.019358" />
      <inertia ixx="9.3E-07" ixy="3.4E-07" ixz="0" iyy="4.38E-06" iyz="0" izz="4.27E-06" />
    </inertial>
    <visual>
      <origin xyz="0 0 0" rpy="0 0 0" />
      <geometry>
        <mesh filename="../meshes/fourier_hand_12dof_v2/R_index_intermediate_link.STL" />
      </geometry>
      <material name="">
        <color rgba="1 1 1 1" />
      </material>
    </visual>
    <collision>
      <origin xyz="0 0 0" rpy="0 0 0" />
      <geometry>
        <mesh filename="../meshes/fourier_hand_12dof_v2/R_index_intermediate_link.STL" />
      </geometry>
    </collision>
  </link>
  <link name="R_index_tip_link">
    <visual>
      <origin xyz="0 0 0" rpy="0 0 0" />
      <geometry>
        <sphere radius="0.005" />
      </geometry>
      <material name="yellow">
        <color rgba="0.9 1 0 1" />
      </material>
    </visual>
  </link>
  <link name="R_middle_proximal_link">
    <inertial>
      <origin xyz="0.016963 0.004834 2.667E-05" rpy="0 0 0" />
      <mass value="0.035619" />
      <inertia ixx="2.19E-06" ixy="-7E-08" ixz="3E-08" iyy="5.29E-06" iyz="0" izz="5.7E-06" />
    </inertial>
    <visual>
      <origin xyz="0 0 0" rpy="0 0 0" />
      <geometry>
        <mesh filename="../meshes/fourier_hand_12dof_v2/R_middle_proximal_link.STL" />
      </geometry>
      <material name="">
        <color rgba="1 1 1 1" />
      </material>
    </visual>
    <collision>
      <origin xyz="0 0 0" rpy="0 0 0" />
      <geometry>
        <mesh filename="../meshes/fourier_hand_12dof_v2/R_middle_proximal_link.STL" />
      </geometry>
    </collision>
  </link>
  <link name="R_middle_intermediate_link">
    <inertial>
      <origin xyz="0.025092 0.00019001 -3.94E-06" rpy="0 0 0" />
      <mass value="0.022377" />
      <inertia ixx="1.09E-06" ixy="5E-07" ixz="0" iyy="6.44E-06" iyz="0" izz="6.32E-06" />
    </inertial>
    <visual>
      <origin xyz="0 0 0" rpy="0 0 0" />
      <geometry>
        <mesh filename="../meshes/fourier_hand_12dof_v2/R_middle_intermediate_link.STL" />
      </geometry>
      <material name="">
        <color rgba="1 1 1 1" />
      </material>
    </visual>
    <collision>
      <origin xyz="0 0 0" rpy="0 0 0" />
      <geometry>
        <mesh filename="../meshes/fourier_hand_12dof_v2/R_middle_intermediate_link.STL" />
      </geometry>
    </collision>
  </link>
  <link name="R_middle_tip_link">
    <visual>
      <origin xyz="0 0 0" rpy="0 0 0" />
      <geometry>
        <sphere radius="0.005" />
      </geometry>
      <material name="yellow">
        <color rgba="0.9 1 0 1" />
      </material>
    </visual>
  </link>
  <link name="R_ring_proximal_link">
    <inertial>
      <origin xyz="0.017015 0.0046443 2.868E-05" rpy="0 0 0" />
      <mass value="0.035619" />
      <inertia ixx="2.19E-06" ixy="-3E-08" ixz="3E-08" iyy="5.3E-06" iyz="0" izz="5.7E-06" />
    </inertial>
    <visual>
      <origin xyz="0 0 0" rpy="0 0 0" />
      <geometry>
        <mesh filename="../meshes/fourier_hand_12dof_v2/R_ring_proximal_link.STL" />
      </geometry>
      <material name="">
        <color rgba="1 1 1 1" />
      </material>
    </visual>
    <collision>
      <origin xyz="0 0 0" rpy="0 0 0" />
      <geometry>
        <mesh filename="../meshes/fourier_hand_12dof_v2/R_ring_proximal_link.STL" />
      </geometry>
    </collision>
  </link>
  <link name="R_ring_intermediate_link">
    <inertial>
      <origin xyz="0.022061 0.00025969 0" rpy="0 0 0" />
      <mass value="0.019358" />
      <inertia ixx="9.3E-07" ixy="3.4E-07" ixz="0" iyy="4.38E-06" iyz="0" izz="4.27E-06" />
    </inertial>
    <visual>
      <origin xyz="0 0 0" rpy="0 0 0" />
      <geometry>
        <mesh filename="../meshes/fourier_hand_12dof_v2/R_ring_intermediate_link.STL" />
      </geometry>
      <material name="">
        <color rgba="1 1 1 1" />
      </material>
    </visual>
    <collision>
      <origin xyz="0 0 0" rpy="0 0 0" />
      <geometry>
        <mesh filename="../meshes/fourier_hand_12dof_v2/R_ring_intermediate_link.STL" />
      </geometry>
    </collision>
  </link>
  <link name="R_ring_tip_link">
    <visual>
      <origin xyz="0 0 0" rpy="0 0 0" />
      <geometry>
        <sphere radius="0.005" />
      </geometry>
      <material name="green">
        <color rgba="0.9 1 0 1" />
      </material>
    </visual>
  </link>
  <link name="R_pinky_proximal_link">
    <inertial>
      <origin xyz="0.017073 0.0044289 2.868E-05" rpy="0 0 0" />
      <mass value="0.035619" />
      <inertia ixx="2.19E-06" ixy="0" ixz="3E-08" iyy="5.3E-06" iyz="-1E-08" izz="5.7E-06" />
    </inertial>
    <visual>
      <origin xyz="0 0 0" rpy="0 0 0" />
      <geometry>
        <mesh filename="../meshes/fourier_hand_12dof_v2/R_pinky_proximal_link.STL" />
      </geometry>
      <material name="">
        <color rgba="1 1 1 1" />
      </material>
    </visual>
    <collision>
      <origin xyz="0 0 0" rpy="0 0 0" />
      <geometry>
        <mesh filename="../meshes/fourier_hand_12dof_v2/R_pinky_proximal_link.STL" />
      </geometry>
    </collision>
  </link>
  <link name="R_pinky_intermediate_link">
    <inertial>
      <origin xyz="0.018249 0.00057564 0" rpy="0 0 0" />
      <mass value="0.01622" />
      <inertia ixx="7.6E-07" ixy="2.1E-07" ixz="0" iyy="2.64E-06" iyz="0" izz="2.57E-06" />
    </inertial>
    <visual>
      <origin xyz="0 0 0" rpy="0 0 0" />
      <geometry>
        <mesh filename="../meshes/fourier_hand_12dof_v2/R_pinky_intermediate_link.STL" />
      </geometry>
      <material name="">
        <color rgba="1 1 1 1" />
      </material>
    </visual>
    <collision>
      <origin xyz="0 0 0" rpy="0 0 0" />
      <geometry>
        <mesh filename="../meshes/fourier_hand_12dof_v2/R_pinky_intermediate_link.STL" />
      </geometry>
    </collision>
  </link>
  <link name="R_pinky_tip_link">
    <visual>
      <origin xyz="0 0 0" rpy="0 0 0" />
      <geometry>
        <sphere radius="0.005" />
      </geometry>
      <material name="yellow">
        <color rgba="0.9 1 0 1" />
      </material>
    </visual>
  </link>
  <joint name="R_hand_wrist_joint" type="fixed">
    <origin xyz="0 0 0" rpy="0 0 0" />
    <parent link="R_hand_base_link" />
    <child link="R_hand_wrist_link" />
    <axis xyz="0 0 0" />
  </joint>


  <joint name="R_thumb_proximal_yaw_joint" type="revolute">
    <origin xyz="0.014 0.012 -0.022546" rpy="-3.1416 0 0" />
    <parent link="R_hand_base_link" />
    <child link="R_thumb_proximal_yaw_link" />
    <axis xyz="0 0 1" />
    <limit lower="-1.3579" upper="0" effort="0" velocity="0" />
  </joint>
  <joint name="R_thumb_proximal_pitch_joint" type="revolute">
    <origin xyz="0.03385 -0.0078588 0.0004" rpy="1.5708 -0.039876 -0.22822" />
    <parent link="R_thumb_proximal_yaw_link" />
    <child link="R_thumb_proximal_pitch_link" />
    <axis xyz="0 0 1" />
    <limit lower="0" upper="1.206" effort="0" velocity="0" />
  </joint>
  <joint name="R_thumb_distal_joint" type="revolute">
    <origin xyz="0.051723 0.0053583 0" rpy="0 9.6078E-05 -0.12589" />
    <parent link="R_thumb_proximal_pitch_link" />
    <child link="R_thumb_distal_link" />
    <axis xyz="0 0 1" />
    <limit lower="0" upper="1.2078" effort="0" velocity="0" />
  </joint>

  <joint name="R_thumb_tip_joint" type="fixed">
    <parent link="R_thumb_distal_link" />
    <child link="R_thumb_tip_link" />
    <origin rpy="0 0 0" xyz="0.037 0.001 0" />
  </joint>


  <joint name="R_index_metacarpal_joint" type="revolute">
    <origin xyz="0.0305 0.0113 -0.088496" rpy="0 1.5295 3.1416" />
    <parent link="R_hand_base_link" />
    <child link="R_index_metacarpal_link" />
    <axis xyz="0 1 0" />
    <limit lower="0" upper="0.295" effort="0" velocity="0" />
  </joint>
  <joint name="R_index_proximal_joint" type="revolute">
    <origin xyz="0.012 0 0" rpy="0 0 -0.041438" />
    <parent link="R_index_metacarpal_link" />
    <child link="R_index_proximal_link" />
    <axis xyz="0 0 1" />
    <limit lower="-1.4172" upper="0" effort="0" velocity="0" />
  </joint>
  <joint name="R_index_intermediate_joint" type="revolute">
    <origin xyz="0.038938 0.0021905 0" rpy="0 0 -0.040106" />
    <parent link="R_index_proximal_link" />
    <child link="R_index_intermediate_link" />
    <axis xyz="0 0 1" />
    <limit lower="-1.4835" upper="0" effort="0" velocity="0" />
  </joint>


  <joint name="R_index_tip_joint" type="fixed">
    <parent link="R_index_intermediate_link" />
    <child link="R_index_tip_link" />
    <origin rpy="0 0 0" xyz="0.047 -0.003 0" />
  </joint>


  <joint name="R_middle_proximal_joint" type="revolute">
    <origin xyz="0.0091 0.0113 -0.10005" rpy="-1.5685 1.5182 1.573" />
    <parent link="R_hand_base_link" />
    <child link="R_middle_proximal_link" />
    <axis xyz="0 0 1" />
    <limit lower="-1.4172" upper="0" effort="0" velocity="0" />
  </joint>
  <joint name="R_middle_intermediate_joint" type="revolute">
    <origin xyz="0.038912 0.0026251 0" rpy="-0.0020273 -7.4325E-05 -0.04236" />
    <parent link="R_middle_proximal_link" />
    <child link="R_middle_intermediate_link" />
    <axis xyz="0 0 1" />
    <limit lower="-1.4835" upper="0" effort="0" velocity="0" />
  </joint>

  <joint name="R_middle_tip_joint" type="fixed">
    <parent link="R_middle_intermediate_link" />
    <child link="R_middle_tip_link" />
    <origin rpy="0 0 0" xyz="0.055 -0.003 0" />
  </joint>


  <joint name="R_ring_proximal_joint" type="revolute">
    <origin xyz="-0.011187 0.0113 -0.10003" rpy="-0.6689 1.504 2.4716" />
    <parent link="R_hand_base_link" />
    <child link="R_ring_proximal_link" />
    <axis xyz="0 0 1" />
    <limit lower="-1.4172" upper="0" effort="0" velocity="0" />
  </joint>
  <joint name="R_ring_intermediate_joint" type="revolute">
    <origin xyz="0.038938 0.0021905 0" rpy="0 0 -0.040106" />
    <parent link="R_ring_proximal_link" />
    <child link="R_ring_intermediate_link" />
    <axis xyz="0 0 1" />
    <limit lower="-1.4835" upper="0" effort="0" velocity="0" />
  </joint>

  <joint name="R_ring_tip_joint" type="fixed">
    <parent link="R_ring_intermediate_link" />
    <child link="R_ring_tip_link" />
    <origin rpy="0 0 0" xyz="0.045 -0.003 0" />
  </joint>


  <joint name="R_pinky_proximal_joint" type="revolute">
    <origin xyz="-0.031472 0.0113 -0.099245" rpy="-0.26739 1.4622 2.8727" />
    <parent link="R_hand_base_link" />
    <child link="R_pinky_proximal_link" />
    <axis xyz="0 0 1" />
    <limit lower="-1.4172" upper="0" effort="0" velocity="0" />
  </joint>
  <joint name="R_pinky_intermediate_joint" type="revolute">
    <origin xyz="0.038963 0.0016981 0" rpy="0 0 -0.036802" />
    <parent link="R_pinky_proximal_link" />
    <child link="R_pinky_intermediate_link" />
    <axis xyz="0 0 1" />
    <limit lower="-1.4835" upper="0" effort="0" velocity="0" />
  </joint>

  <joint name="R_pinky_tip_joint" type="fixed">
    <parent link="R_pinky_intermediate_link" />
    <child link="R_pinky_tip_link" />
    <origin rpy="0 0 0" xyz="0.038 -0.003 0" />
  </joint>

<joint name="R_hand_base_joint" type="fixed"><parent link="right_end_effector_link" /><child link="R_hand_base_link" /><origin rpy="0 0 0" xyz="0 0 0" /></joint></robot>